<?xml version="1.0" encoding="utf-8"?>
<!-- =================================================================================== -->
<!-- |    This document was autogenerated by xacro from ic120.xacro                    | -->
<!-- |    EDITING THIS FILE BY HAND IS NOT RECOMMENDED                                 | -->
<!-- =================================================================================== -->
<robot name="ic120">
  <!-- ros_control plugin -->
  <gazebo>
    <plugin filename="libgazebo_ros_control.so" name="gazebo_ros_control">
      <robotNamespace>/ic120</robotNamespace>
      <robotSimType>gazebo_ros_control/DefaultRobotHWSim</robotSimType>
    </plugin>
  </gazebo>
  <!-- Link1 -->
  <gazebo reference="link1">
    <material>ic120texture</material>
  </gazebo>
  <!-- Link2 -->
  <gazebo reference="link2">
    <material>ic120texture</material>
  </gazebo>
  <gazebo reference="link3">
    <material>ic120texture</material>
  </gazebo>
  <gazebo reference="link4">
    <material>ic120texture</material>
  </gazebo>
  <!--
	<material name="black">
		<color rgba="0.0 0.0 0.0 1.0"/>
	</material>

	<material name="blue">
		<color rgba="0.0 0.0 0.8 1.0"/>
	</material>

	<material name="green">
		<color rgba="0.0 0.8 0.0 1.0"/>
	</material>

	<material name="grey">
		<color rgba="0.2 0.2 0.2 1.0"/>
	</material>

	<material name="orange">
		<color rgba="${255/255} ${108/255} ${10/255} 1.0"/>
	</material>

	<material name="brown">
		<color rgba="${222/255} ${207/255} ${195/255} 1.0"/>
	</material>

	<material name="red">
		<color rgba="0.8 0.0 0.0 1.0"/>
	</material>

	<material name="white">
		<color rgba="1.0 1.0 1.0 1.0"/>
	</material>

	<material name="model01color">
		<color rgba="0.0 1.0 1.0 0.7"/>
	</material>
	-->
  <!-- Used for fixing robot to Gazebo 'base_link' -->
  <link name="world"/>
  <joint name="fixed" type="fixed">
    <parent link="world"/>
    <child link="link1"/>
  </joint>
  <!-- Base Link -->
  <link name="link1">
    <visual>
      <geometry>
        <mesh filename="package://meshes/ic120-body.dae"/>
      </geometry>
    </visual>
    <collision>
      <geometry>
        <mesh filename="package://meshes/ic120-body.dae"/>
      </geometry>
    </collision>
    <inertial>
      <origin rpy="0 0 0" xyz="0.8963 0.1313 1.35"/>
      <mass value="1"/>
      <inertia ixx="1.0" ixy="0.0" ixz="0.0" iyy="1.0" iyz="0.0" izz="1.0"/>
    </inertial>
  </link>
  <!-- bucket axis -->
  <joint name="joint1" type="revolute">
    <origin xyz="-3.015332 0 0.946052"/>
    <axis xyz="0 1 0"/>
    <parent link="link1"/>
    <child link="link2"/>
    <limit effort="30" lower="-1.1344640138" upper="0" velocity="6.159937255"/>
    <!-- max bucket angle 65 deg -->
    <!--dynamics damping="0.7"/-->
  </joint>
  <link name="link2">
    <visual>
      <origin xyz="0 0 0"/>
      <geometry>
        <mesh filename="package://meshes/ic120-bucket.dae"/>
      </geometry>
    </visual>
    <collision>
      <origin xyz="0 0 0"/>
      <geometry>
        <mesh filename="package://meshes/ic120-bucket.dae"/>
      </geometry>
    </collision>
    <inertial>
      <origin rpy="0 0 0" xyz="1.978 0.0181 0.773"/>
      <mass value="1"/>
      <inertia ixx="1.0" ixy="0.0" ixz="0.0" iyy="1.0" iyz="0.0" izz="1.0"/>
    </inertial>
  </link>
  <!-- cylinder outer axis -->
  <joint name="joint2" type="continuous">
    <origin xyz="-0.75792 0 0.73083"/>
    <axis xyz="0 1 0"/>
    <parent link="link1"/>
    <child link="link3"/>
    <mimic joint="joint1" multiplier="-0.088"/>
  </joint>
  <!-- cylinder outer angle -->
  <gazebo>
    <plugin filename="libroboticsgroup_upatras_gazebo_mimic_joint_plugin.so" name="joint2_mimic_joint_plugin">
      <joint>joint1</joint>
      <mimicJoint>joint2</mimicJoint>
      <multiplier>-0.088</multiplier>
      <!-- bucket 65 deg => cylinder outer 5.72 deg -->
      <offset>0</offset>
      <robotNamespace>/ic120</robotNamespace>
    </plugin>
  </gazebo>
  <link name="link3">
    <visual>
      <origin xyz="0 0 0"/>
      <geometry>
        <mesh filename="package://meshes/ic120-cylinder1.dae"/>
      </geometry>
    </visual>
    <collision>
      <origin xyz="0 0 0"/>
      <geometry>
        <mesh filename="package://meshes/ic120-cylinder1.dae"/>
      </geometry>
    </collision>
    <inertial>
      <origin rpy="0 0 0" xyz="-0.4842 0 0.1667"/>
      <mass value="1"/>
      <inertia ixx="1.0" ixy="0.0" ixz="0.0" iyy="1.0" iyz="0.0" izz="1.0"/>
    </inertial>
  </link>
  <!-- cylinder inner prismatic joint -->
  <joint name="joint3" type="prismatic">
    <origin xyz="0 0 0"/>
    <parent link="link3"/>
    <child link="link4"/>
    <axis xyz="-1.4989 0 0.51788"/>
    <limit effort="30" lower="-1" upper="1" velocity="6.159937255"/>
    <mimic joint="joint1" multiplier="-0.705178824776"/>
  </joint>
  <!-- cylinder inner position -->
  <gazebo>
    <plugin filename="libroboticsgroup_upatras_gazebo_mimic_joint_plugin.so" name="joint3_mimic_joint_plugin">
      <joint>joint1</joint>
      <mimicJoint>joint3</mimicJoint>
      <multiplier>-0.705178824776</multiplier>
      <!-- bucket 65 deg => cylinder inner 0.8 m -->
      <offset>0</offset>
      <robotNamespace>/ic120</robotNamespace>
    </plugin>
  </gazebo>
  <link name="link4">
    <visual>
      <origin xyz="0 0 0"/>
      <geometry>
        <mesh filename="package://meshes/ic120-cylinder2.dae"/>
      </geometry>
    </visual>
    <collision>
      <origin xyz="0 0 0"/>
      <geometry>
        <mesh filename="package://meshes/ic120-cylinder2.dae"/>
      </geometry>
    </collision>
    <inertial>
      <origin rpy="0 0 0" xyz="-0.8807 0 0.3033"/>
      <mass value="1"/>
      <inertia ixx="1.0" ixy="0.0" ixz="0.0" iyy="1.0" iyz="0.0" izz="1.0"/>
    </inertial>
  </link>
  <transmission name="tran1">
    <type>transmission_interface/SimpleTransmission</type>
    <joint name="joint1">
      <hardwareInterface>hardware_interface/EffortJointInterface</hardwareInterface>
    </joint>
    <actuator name="motor1">
      <hardwareInterface>hardware_interface/EffortJointInterface</hardwareInterface>
      <mechanicalReduction>1</mechanicalReduction>
    </actuator>
  </transmission>
</robot>

