<?xml version="1.0" ?>
<!-- =================================================================================== -->
<!-- |    This document was autogenerated by xacro from zx200.xacro                    | -->
<!-- |    EDITING THIS FILE BY HAND IS NOT RECOMMENDED                                 | -->
<!-- =================================================================================== -->
<robot name="zx200">
  <!-- Import all Gazebo-customization elements, including Gazebo colors -->
  <!-- <xacro:include filename="$(find zx200_description)/urdf/zx200.gazebo" /> -->
  <!-- Import Rviz colors -->
  <!-- <xacro:include filename="$(find zx200_description)/urdf/materials.xacro" /> -->
  <!-- Used for fixing robot to Gazebo 'base_link' -->
  <!--link name="link1"/>
  <joint name="fixed" type="fixed">
    <parent link="link1"/>
    <child link="link2"/>
  </joint-->
  <!-- Base Link -->
  <link name="base_link">
    <visual>
      <geometry>
        <mesh filename="package://meshes/zx200-crawler.dae"/>
      </geometry>
    </visual>
    <collision>
      <geometry>
        <mesh filename="package://meshes/zx200-crawler.dae"/>
      </geometry>
    </collision>
    <inertial>
      <origin rpy="0 0 0" xyz="0 0 0"/>
      <mass value="0.03"/>
      <inertia ixx="1.0" ixy="0.0" ixz="0.0" iyy="1.0" iyz="0.0" izz="1.0"/>
    </inertial>
  </link>
  <joint name="left_front_wheel_joint" type="continuous">
    <origin rpy="-1.57079632679 0 0" xyz="1.685 1.095 0.395"/>
    <parent link="base_link"/>
    <child link="left_front_wheel_link"/>
    <axis xyz="0 0 1"/>
  </joint>
  <transmission name="left_front_wheel_trans" type="SimpleTransmission">
    <type>transmission_interface/SimpleTransmission</type>
    <actuator name="left_front_wheel_motor">
      <mechanicalReduction>1</mechanicalReduction>
    </actuator>
    <joint name="left_front_wheel_joint">
      <hardwareInterface>hardware_interface/VelocityJointInterface</hardwareInterface>
    </joint>
  </transmission>
  <link name="left_front_wheel_link">
    <inertial>
      <origin rpy="0 0 0" xyz="0 0 0"/>
      <mass value="0.1"/>
      <inertia ixx="0.0001" ixy="0.0" ixz="0.0" iyy="0.0001" iyz="0.0" izz="0.0001"/>
    </inertial>
    <visual>
      <geometry>
        <cylinder length="0.001" radius="0.001"/>
      </geometry>
      <!--material name="red"/-->
    </visual>
    <collision>
      <geometry>
        <cylinder length="0.6" radius="0.395"/>
      </geometry>
    </collision>
  </link>
  <gazebo reference="left_front_wheel_link">
    <!--material>Gazebo/Red</material-->
    <mu1 value="2.5"/>
    <mu2 value="2.5"/>
    <kp value="50000"/>
    <kd value="10"/>
  </gazebo>
  <joint name="left_middle_wheel_joint" type="continuous">
    <origin rpy="-1.57079632679 0 0" xyz="0 1.095 0.395"/>
    <parent link="base_link"/>
    <child link="left_middle_wheel_link"/>
    <axis xyz="0 0 1"/>
  </joint>
  <transmission name="left_middle_wheel_trans" type="SimpleTransmission">
    <type>transmission_interface/SimpleTransmission</type>
    <actuator name="left_middle_wheel_motor">
      <mechanicalReduction>1</mechanicalReduction>
    </actuator>
    <joint name="left_middle_wheel_joint">
      <hardwareInterface>hardware_interface/VelocityJointInterface</hardwareInterface>
    </joint>
  </transmission>
  <link name="left_middle_wheel_link">
    <inertial>
      <origin rpy="0 0 0" xyz="0 0 0"/>
      <mass value="0.1"/>
      <inertia ixx="0.0001" ixy="0.0" ixz="0.0" iyy="0.0001" iyz="0.0" izz="0.0001"/>
    </inertial>
    <visual>
      <geometry>
        <cylinder length="0.001" radius="0.001"/>
      </geometry>
      <!--material name="red"/-->
    </visual>
    <collision>
      <geometry>
        <cylinder length="0.6" radius="0.395"/>
      </geometry>
    </collision>
  </link>
  <gazebo reference="left_middle_wheel_link">
    <!--material>Gazebo/Red</material-->
    <mu1 value="2.5"/>
    <mu2 value="2.5"/>
    <kp value="50000"/>
    <kd value="10"/>
  </gazebo>
  <joint name="left_rear_wheel_joint" type="continuous">
    <origin rpy="-1.57079632679 0 0" xyz="-1.685 1.095 0.395"/>
    <parent link="base_link"/>
    <child link="left_rear_wheel_link"/>
    <axis xyz="0 0 1"/>
  </joint>
  <transmission name="left_rear_wheel_trans" type="SimpleTransmission">
    <type>transmission_interface/SimpleTransmission</type>
    <actuator name="left_rear_wheel_motor">
      <mechanicalReduction>1</mechanicalReduction>
    </actuator>
    <joint name="left_rear_wheel_joint">
      <hardwareInterface>hardware_interface/VelocityJointInterface</hardwareInterface>
    </joint>
  </transmission>
  <link name="left_rear_wheel_link">
    <inertial>
      <origin rpy="0 0 0" xyz="0 0 0"/>
      <mass value="0.1"/>
      <inertia ixx="0.0001" ixy="0.0" ixz="0.0" iyy="0.0001" iyz="0.0" izz="0.0001"/>
    </inertial>
    <visual>
      <geometry>
        <cylinder length="0.001" radius="0.001"/>
      </geometry>
      <!--material name="red"/-->
    </visual>
    <collision>
      <geometry>
        <cylinder length="0.6" radius="0.395"/>
      </geometry>
    </collision>
  </link>
  <gazebo reference="left_rear_wheel_link">
    <!--material>Gazebo/Red</material-->
    <mu1 value="2.5"/>
    <mu2 value="2.5"/>
    <kp value="50000"/>
    <kd value="10"/>
  </gazebo>
  <joint name="right_front_wheel_joint" type="continuous">
    <origin rpy="-1.57079632679 0 0" xyz="1.685 -1.095 0.395"/>
    <parent link="base_link"/>
    <child link="right_front_wheel_link"/>
    <axis xyz="0 0 1"/>
  </joint>
  <transmission name="right_front_wheel_trans" type="SimpleTransmission">
    <type>transmission_interface/SimpleTransmission</type>
    <actuator name="right_front_wheel_motor">
      <mechanicalReduction>1</mechanicalReduction>
    </actuator>
    <joint name="right_front_wheel_joint">
      <hardwareInterface>hardware_interface/VelocityJointInterface</hardwareInterface>
    </joint>
  </transmission>
  <link name="right_front_wheel_link">
    <inertial>
      <origin rpy="0 0 0" xyz="0 0 0"/>
      <mass value="0.1"/>
      <inertia ixx="0.0001" ixy="0.0" ixz="0.0" iyy="0.0001" iyz="0.0" izz="0.0001"/>
    </inertial>
    <visual>
      <geometry>
        <cylinder length="0.001" radius="0.001"/>
      </geometry>
      <!--material name="red"/-->
    </visual>
    <collision>
      <geometry>
        <cylinder length="0.6" radius="0.395"/>
      </geometry>
    </collision>
  </link>
  <gazebo reference="right_front_wheel_link">
    <!--material>Gazebo/Red</material-->
    <mu1 value="2.5"/>
    <mu2 value="2.5"/>
    <kp value="50000"/>
    <kd value="10"/>
  </gazebo>
  <joint name="right_middle_wheel_joint" type="continuous">
    <origin rpy="-1.57079632679 0 0" xyz="0 -1.095 0.395"/>
    <parent link="base_link"/>
    <child link="right_middle_wheel_link"/>
    <axis xyz="0 0 1"/>
  </joint>
  <transmission name="right_middle_wheel_trans" type="SimpleTransmission">
    <type>transmission_interface/SimpleTransmission</type>
    <actuator name="right_middle_wheel_motor">
      <mechanicalReduction>1</mechanicalReduction>
    </actuator>
    <joint name="right_middle_wheel_joint">
      <hardwareInterface>hardware_interface/VelocityJointInterface</hardwareInterface>
    </joint>
  </transmission>
  <link name="right_middle_wheel_link">
    <inertial>
      <origin rpy="0 0 0" xyz="0 0 0"/>
      <mass value="0.1"/>
      <inertia ixx="0.0001" ixy="0.0" ixz="0.0" iyy="0.0001" iyz="0.0" izz="0.0001"/>
    </inertial>
    <visual>
      <geometry>
        <cylinder length="0.001" radius="0.001"/>
      </geometry>
      <!--material name="red"/-->
    </visual>
    <collision>
      <geometry>
        <cylinder length="0.6" radius="0.395"/>
      </geometry>
    </collision>
  </link>
  <gazebo reference="right_middle_wheel_link">
    <!--material>Gazebo/Red</material-->
    <mu1 value="2.5"/>
    <mu2 value="2.5"/>
    <kp value="50000"/>
    <kd value="10"/>
  </gazebo>
  <joint name="right_rear_wheel_joint" type="continuous">
    <origin rpy="-1.57079632679 0 0" xyz="-1.685 -1.095 0.395"/>
    <parent link="base_link"/>
    <child link="right_rear_wheel_link"/>
    <axis xyz="0 0 1"/>
  </joint>
  <transmission name="right_rear_wheel_trans" type="SimpleTransmission">
    <type>transmission_interface/SimpleTransmission</type>
    <actuator name="right_rear_wheel_motor">
      <mechanicalReduction>1</mechanicalReduction>
    </actuator>
    <joint name="right_rear_wheel_joint">
      <hardwareInterface>hardware_interface/VelocityJointInterface</hardwareInterface>
    </joint>
  </transmission>
  <link name="right_rear_wheel_link">
    <inertial>
      <origin rpy="0 0 0" xyz="0 0 0"/>
      <mass value="0.1"/>
      <inertia ixx="0.0001" ixy="0.0" ixz="0.0" iyy="0.0001" iyz="0.0" izz="0.0001"/>
    </inertial>
    <visual>
      <geometry>
        <cylinder length="0.001" radius="0.001"/>
      </geometry>
      <!--material name="red"/-->
    </visual>
    <collision>
      <geometry>
        <cylinder length="0.6" radius="0.395"/>
      </geometry>
    </collision>
  </link>
  <gazebo reference="right_rear_wheel_link">
    <!--material>Gazebo/Red</material-->
    <mu1 value="2.5"/>
    <mu2 value="2.5"/>
    <kp value="50000"/>
    <kd value="10"/>
  </gazebo>
  <!-- body axis -->
  <joint name="swing_joint" type="continuous">
    <origin xyz="0.10787 -0.034301 1.1206"/>
    <axis xyz="0 0 1"/>
    <parent link="base_link"/>
    <child link="body_link"/>
  </joint>
  <link name="body_link">
    <visual>
      <origin xyz="0 0 0"/>
      <geometry>
        <mesh filename="package://meshes/zx200-body.dae"/>
      </geometry>
    </visual>
    <collision>
      <origin xyz="0 0 0"/>
      <geometry>
        <mesh filename="package://meshes/zx200-body.dae"/>
      </geometry>
    </collision>
    <inertial>
      <origin rpy="0 0 0" xyz="0 0 0"/>
      <mass value="0.03"/>
      <inertia ixx="1.0" ixy="0.0" ixz="0.0" iyy="1.0" iyz="0.0" izz="1.0"/>
    </inertial>
  </link>
  <!-- boom axis -->
  <joint name="boom_joint" type="revolute">
    <origin rpy="0 0.6108652382 0" xyz="0.22767 -0.040187 0.83669"/>
    <axis xyz="0 1 0"/>
    <parent link="body_link"/>
    <child link="boom_link"/>
    <limit effort="500" lower="-0.3490658503988659" upper="0.9599310885968813" velocity="6.159937255"/>
  </joint>
  <link name="boom_link">
    <visual>
      <origin xyz="0 0 0"/>
      <geometry>
        <mesh filename="package://meshes/zx200-boom.dae"/>
      </geometry>
    </visual>
    <collision>
      <origin xyz="0 0 0"/>
      <geometry>
        <mesh filename="package://meshes/zx200-boom.dae"/>
      </geometry>
    </collision>
    <inertial>
      <origin rpy="0 0 0" xyz="0 0 0"/>
      <mass value="0.03"/>
      <inertia ixx="1.0" ixy="0.0" ixz="0.0" iyy="1.0" iyz="0.0" izz="1.0"/>
    </inertial>
  </link>
  <joint name="arm_joint" type="revolute">
    <origin rpy="0 0.2617993878 0" xyz="4.7878 0.010957 2.9959"/>
    <axis xyz="0 1 0"/>
    <parent link="boom_link"/>
    <child link="arm_link"/>
    <limit effort="500" lower="0.7853981633974483" upper="2.530727415391778" velocity="6.159937255"/>
  </joint>
  <link name="arm_link">
    <visual>
      <origin xyz="0 0 0"/>
      <geometry>
        <mesh filename="package://meshes/zx200-arm.dae"/>
      </geometry>
    </visual>
    <collision>
      <origin xyz="0 0 0"/>
      <geometry>
        <mesh filename="package://meshes/zx200-arm.dae"/>
      </geometry>
    </collision>
    <inertial>
      <origin rpy="0 0 0" xyz="0 0 0"/>
      <mass value="0.03"/>
      <inertia ixx="1.0" ixy="0.0" ixz="0.0" iyy="1.0" iyz="0.0" izz="1.0"/>
    </inertial>
  </link>
  <!-- bucket axis -->
  <joint name="bucket_joint" type="revolute">
    <origin rpy="0 -0.3490658504 0" xyz="1.8954 -0.023546 2.1809"/>
    <axis xyz="0 1 0"/>
    <parent link="arm_link"/>
    <child link="bucket_link"/>
    <limit effort="500" lower="-1.2217304763960306" upper="1.3962634015954636" velocity="6.159937255"/>
  </joint>
  <link name="bucket_link">
    <visual>
      <origin xyz="0 0 0"/>
      <geometry>
        <mesh filename="package://meshes/zx200-bucket.dae"/>
      </geometry>
    </visual>
    <collision>
      <origin xyz="0 0 0"/>
      <geometry>
        <mesh filename="package://meshes/zx200-bucket.dae"/>
      </geometry>
    </collision>
    <inertial>
      <origin rpy="0 0 0" xyz="0 0 0"/>
      <mass value="0.03"/>
      <inertia ixx="1.0" ixy="0.0" ixz="0.0" iyy="1.0" iyz="0.0" izz="1.0"/>
    </inertial>
  </link>
  <link name="bucket_end_link">
    <visual>
      <origin rpy="0 0 0" xyz="0 0 0"/>
      <geometry>
        <box size="0.001 0.001 0.001"/>
      </geometry>
      <material name="red"/>
    </visual>
    <inertial>
      <origin xyz="0 0 0"/>
      <mass value="1.0e-03"/>
      <inertia ixx="1.0e-03" ixy="0.0" ixz="0.0" iyy="1.0e-03" iyz="0.0" izz="1.0e-03"/>
    </inertial>
  </link>
  <joint name="bucket_end_joint" type="revolute">
    <parent link="bucket_link"/>
    <child link="bucket_end_link"/>
    <axis xyz="1 0 0"/>
    <origin rpy="0 0 0" xyz="1.2 0 1"/>
    <limit effort="1" lower="-3.14" upper="3.14" velocity="0.5"/>
  </joint>
    
  <transmission name="tran1">
    <type>transmission_interface/SimpleTransmission</type>
    <joint name="swing_joint">
      <hardwareInterface>hardware_interface/EffortJointInterface</hardwareInterface>
    </joint>
    <actuator name="motor1">
      <hardwareInterface>hardware_interface/EffortJointInterface</hardwareInterface>
      <mechanicalReduction>1</mechanicalReduction>
    </actuator>
  </transmission>
  <transmission name="tran2">
    <type>transmission_interface/SimpleTransmission</type>
    <joint name="boom_joint">
      <hardwareInterface>hardware_interface/EffortJointInterface</hardwareInterface>
    </joint>
    <actuator name="motor2">
      <hardwareInterface>hardware_interface/EffortJointInterface</hardwareInterface>
      <mechanicalReduction>1</mechanicalReduction>
    </actuator>
  </transmission>
  <transmission name="tran3">
    <type>transmission_interface/SimpleTransmission</type>
    <joint name="arm_joint">
      <hardwareInterface>hardware_interface/EffortJointInterface</hardwareInterface>
    </joint>
    <actuator name="motor3">
      <hardwareInterface>hardware_interface/EffortJointInterface</hardwareInterface>
      <mechanicalReduction>1</mechanicalReduction>
    </actuator>
  </transmission>
  <transmission name="tran4">
    <type>transmission_interface/SimpleTransmission</type>
    <joint name="bucket_joint">
      <hardwareInterface>hardware_interface/EffortJointInterface</hardwareInterface>
    </joint>
    <actuator name="motor4">
      <hardwareInterface>hardware_interface/EffortJointInterface</hardwareInterface>
      <mechanicalReduction>1</mechanicalReduction>
    </actuator>
  </transmission>
  <transmission name="dummy_trans1">
    <type>transmission_interface/SimpleTransmission</type>
    <joint name="bucket_end_joint">
      <hardwareInterface>hardware_interface/PositionJointInterface</hardwareInterface>
    </joint>
    <actuator name="dummy_motor1">
      <hardwareInterface>hardware_interface/PositionJointInterface</hardwareInterface>
      <mechanicalReduction>1</mechanicalReduction>
    </actuator>
  </transmission>

  <disable_collision link1="base_link" link2="body_link"></disable_collision>
  <disable_collision link1="body_link" link2="boom_link"></disable_collision>
  <disable_collision link1="boom_link" link2="arm_link"></disable_collision>
  <disable_collision link1="arm_link" link2="bucket_link"></disable_collision>
  <disable_collision link1="bucket_link" link2="bucket_end_link"></disable_collision>
</robot>