<?xml version="1.0" encoding="utf-8"?>
<!-- =================================================================================== -->
<!-- |    This document was autogenerated by xacro from c30-r.xacro                    | -->
<!-- |    EDITING THIS FILE BY HAND IS NOT RECOMMENDED                                 | -->
<!-- =================================================================================== -->
<robot name="c30-r">
  <material name="grey">
    <color rgba="0.4 0.4 0.4 1.0"/>
  </material>
  <material name="yellow">
    <color rgba="1.0 1.0 0.0 1.0"/>
  </material>
  <link name="base_link"/>
  <link name="body_link">
    <visual>
      <origin rpy="1.57079632679 0 3.14159265359" xyz="0 0 0.0"/>
      <geometry>
        <mesh filename="package://c30-r_description/meshes/carrier.stl" scale="0.001 0.001 0.001"/>
      </geometry>
      <material name="grey"/>
    </visual>
    <collision>
      <origin rpy="1.57079632679 0 3.14159265359" xyz="0 0 0.0"/>
      <geometry>
        <mesh filename="package://c30-r_description/meshes/carrier.stl" scale="0.001 0.001 0.001"/>
      </geometry>
    </collision>
    <inertial>
      <mass value="2429"/>
      <!--mass value is listed in maintenance manual -->
      <origin rpy="0 0 0" xyz="-0.389 -0.01 0.438"/>
      <inertia ixx="893.2" ixy="264.1" ixz="-22.5" iyy="1904.5" iyz="-5.5" izz="1743.4"/>
    </inertial>
  </link>
  <link name="body_hinge_link">
    <inertial>
      <mass value="0.001"/>
      <origin rpy="0 0 0" xyz="0 0 0"/>
      <inertia ixx="0.001" ixy="0" ixz="0" iyy="0.001" iyz="0" izz="0.001"/>
    </inertial>
  </link>
  <link name="bed_link">
    <visual>
      <origin rpy="1.57079632679 0 3.14159265359" xyz="0 0 0.0"/>
      <geometry>
        <mesh filename="package://c30-r_description/meshes/bed.stl" scale="0.001 0.001 0.001"/>
      </geometry>
      <material name="yellow"/>
    </visual>
    <collision>
      <origin rpy="1.57079632679 0 3.14159265359" xyz="0 0 0.0"/>
      <geometry>
        <mesh filename="package://c30-r_description/meshes/bed.stl" scale="0.001 0.001 0.001"/>
      </geometry>
    </collision>
    <inertial>
      <mass value="346"/>
      <!--mass value is listed in maintenance manual -->
      <origin rpy="0 0 0" xyz="-1.5 0.0 0.892"/>
      <inertia ixx="92.3" ixy="-4.0" ixz="-0.1" iyy="206.5" iyz="-0.04" izz="140.5"/>
    </inertial>
  </link>
  <link name="bed_hinge_link">
    <inertial>
      <mass value="0.001"/>
      <origin rpy="0 0 0" xyz="0 0 0"/>
      <inertia ixx="0.001" ixy="0" ixz="0" iyy="0.001" iyz="0" izz="0.001"/>
    </inertial>
  </link>
  <joint name="base_to_body" type="fixed">
    <origin rpy="0 0 0" xyz="0 0 0"/>
    <parent link="base_link"/>
    <child link="body_link"/>
  </joint>
  <joint name="body_to_body_hinge" type="fixed">
    <origin rpy="0 0 1.57079632679" xyz="-2.25 0 0.85"/>
    <parent link="body_link"/>
    <child link="body_hinge_link"/>
  </joint>
  <joint name="body_hinge_to_bed_hinge" type="revolute">
    <origin rpy="0 0 0" xyz="0 0 0"/>
    <parent link="body_hinge_link"/>
    <child link="bed_hinge_link"/>
    <limit effort="1" lower="-1.57079632679" upper="0.0" velocity="1"/>
  </joint>
  <joint name="bed_to_bed_hinge" type="fixed">
    <origin rpy="0 0 -1.57079632679" xyz="0 -2.25 -0.85"/>
    <parent link="bed_hinge_link"/>
    <child link="bed_link"/>
  </joint>
</robot>

