<?xml version="1.0" ?>
<!-- =================================================================================== -->
<!-- |    This document was autogenerated by xacro from ic120_gazebo.xacro             | -->
<!-- |    EDITING THIS FILE BY HAND IS NOT RECOMMENDED                                 | -->
<!-- =================================================================================== -->
<robot name="ic120">
  <!-- <xacro:property name="model_offset_x" value="-1.5" />
  <xacro:property name="model_offset_y" value="-3.1" /> -->
  <!-- <xacro:property name="model_offset_x" value="-1.5" />
  <xacro:property name="model_offset_y" value="-3.1" /> -->
  <link name="base_link">
    <visual>
      <geometry>
        <mesh filename="package://ic120_model/mesh/track_frame.stl"/>
      </geometry>
      <origin rpy="0 0 1.57079632675" xyz="3.1 -1.5 0"/>
      <material name="Gray">
        <color rgba="0.7 0.7 0.7 1.0"/>
      </material>
    </visual>
    <inertial>
      <mass value="1"/>
      <inertia ixx="1" ixy="0.0" ixz="0.0" iyy="1" iyz="0.0" izz="1"/>
    </inertial>
  </link>
  <link name="track_belt_link">
    <visual>
      <geometry>
        <mesh filename="package://ic120_model/mesh/track_belt.stl"/>
      </geometry>
      <origin rpy="0 0 1.57079632675" xyz="3.1 -1.5 0"/>
      <material name="Black">
        <color rgba="0 0 0 1.0"/>
      </material>
    </visual>
    <inertial>
      <mass value="1"/>
      <inertia ixx="1" ixy="0.0" ixz="0.0" iyy="1" iyz="0.0" izz="1"/>
    </inertial>
  </link>
  <joint name="track_belt_joint" type="fixed">
    <origin rpy="0 0 0" xyz="0 0 0"/>
    <parent link="base_link"/>
    <child link="track_belt_link"/>
    <axis xyz="0 0 1"/>
  </joint>
  <link name="upper_frame_link">
    <visual>
      <geometry>
        <mesh filename="package://ic120_model/mesh/upper_frame.stl"/>
      </geometry>
      <origin rpy="0 0 1.57079632675" xyz="3.1 -1.5 0"/>
      <material name="Teal">
        <color rgba="0 0.5 0.5 1.0"/>
      </material>
    </visual>
    <inertial>
      <mass value="1"/>
      <inertia ixx="1" ixy="0.0" ixz="0.0" iyy="1" iyz="0.0" izz="1"/>
    </inertial>
  </link>
  <joint name="upper_frame_joint" type="fixed">
    <origin rpy="0 0 0" xyz="0 0 0"/>
    <parent link="base_link"/>
    <child link="upper_frame_link"/>
    <axis xyz="0 0 1"/>
  </joint>
  <link name="cabin_link">
    <visual>
      <geometry>
        <mesh filename="package://ic120_model/mesh/cabin.stl"/>
      </geometry>
      <origin rpy="0 0 1.57079632675" xyz="3.1 -1.5 0"/>
      <material name="Black">
        <color rgba="0 0 0 1.0"/>
      </material>
    </visual>
    <inertial>
      <mass value="1"/>
      <inertia ixx="1" ixy="0.0" ixz="0.0" iyy="1" iyz="0.0" izz="1"/>
    </inertial>
  </link>
  <joint name="cabin_joint" type="fixed">
    <origin rpy="0 0 0" xyz="0 0 0"/>
    <parent link="base_link"/>
    <child link="cabin_link"/>
    <axis xyz="0 0 1"/>
  </joint>
  <link name="cabin_window_link">
    <visual>
      <geometry>
        <mesh filename="package://ic120_model/mesh/cabin_window.stl"/>
      </geometry>
      <origin rpy="0 0 1.57079632675" xyz="3.1 -1.5 0"/>
      <material name="Gray">
        <color rgba="0.7 0.7 0.7 0.2"/>
      </material>
    </visual>
    <inertial>
      <mass value="1"/>
      <inertia ixx="1" ixy="0.0" ixz="0.0" iyy="1" iyz="0.0" izz="1"/>
    </inertial>
  </link>
  <joint name="cabin_window_joint" type="fixed">
    <origin rpy="0 0 0" xyz="0 0 0"/>
    <parent link="base_link"/>
    <child link="cabin_window_link"/>
    <axis xyz="0 0 1"/>
  </joint>
  <link name="vessel_pin_link">
    <visual>
      <geometry>
        <mesh filename="package://ic120_model/mesh/vessel.stl"/>
      </geometry>
      <origin rpy="0 0 1.57079632675" xyz="5.4 -1.5 -1.55"/>
      <material name="Teal">
        <color rgba="0 0.5 0.5 1.0"/>
      </material>
    </visual>
    <inertial>
      <origin xyz="0 0 0"/>
      <mass value="1.0e-03"/>
      <inertia ixx="1.0e-03" ixy="0.0" ixz="0.0" iyy="1.0e-03" iyz="0.0" izz="1.0e-03"/>
    </inertial>
  </link>
  <joint name="vessel_pin_joint" type="revolute">
    <origin rpy="0 0 0" xyz="-2.30 0 1.55"/>
    <parent link="base_link"/>
    <child link="vessel_pin_link"/>
    <axis xyz="0 1 0"/>
    <limit effort="1" lower="-3.14" upper="0" velocity="0.5"/>
  </joint>
  <link name="vessel_link"/>
  <joint name="vessel_joint" type="fixed">
    <origin rpy="0 0 0" xyz="-1.6 0 1.5"/>
    <parent link="base_link"/>
    <child link="vessel_link"/>
    <axis xyz="0 0 1"/>
  </joint>
  <joint name="left_middle_wheel_joint" type="continuous">
    <origin rpy="-1.5707963267948966 0 0" xyz="0 1 0.5"/>
    <parent link="base_link"/>
    <child link="left_middle_wheel_link"/>
    <axis xyz="0 0 1"/>
  </joint>
  <transmission name="left_middle_wheel_trans" type="SimpleTransmission">
    <type>transmission_interface/SimpleTransmission</type>
    <actuator name="left_middle_wheel_motor">
      <mechanicalReduction>1</mechanicalReduction>
    </actuator>
    <joint name="left_middle_wheel_joint">
      <hardwareInterface>hardware_interface/VelocityJointInterface</hardwareInterface>
    </joint>
  </transmission>
  <link name="left_middle_wheel_link">
    <inertial>
      <origin rpy="0 0 0" xyz="0 0 0"/>
      <mass value="10"/>
      <inertia ixx="5" ixy="0.0" ixz="0.0" iyy="5" iyz="0.0" izz="5"/>
    </inertial>
    <!-- <visual>
        <geometry>
          <cylinder radius="0.5" length="0.5" />
        </geometry>
      </visual> -->
    <collision>
      <geometry>
        <cylinder length="0.1" radius="0.5"/>
      </geometry>
    </collision>
  </link>
  <gazebo reference="left_middle_wheel_link">
    <!--material>Gazebo/Red</material-->
    <mu1 value="0.7"/>
    <mu2 value="0.6"/>
    <kp value="7.5e+5"/>
    <kd value="0.001"/>
  </gazebo>
  <joint name="left_front1_wheel_joint" type="continuous">
    <origin rpy="-1.5707963267948966 0 0" xyz="0.5 1 0.5"/>
    <parent link="base_link"/>
    <child link="left_front1_wheel_link"/>
    <axis xyz="0 0 1"/>
  </joint>
  <transmission name="left_front1_wheel_trans" type="SimpleTransmission">
    <type>transmission_interface/SimpleTransmission</type>
    <actuator name="left_front1_wheel_motor">
      <mechanicalReduction>1</mechanicalReduction>
    </actuator>
    <joint name="left_front1_wheel_joint">
      <hardwareInterface>hardware_interface/VelocityJointInterface</hardwareInterface>
    </joint>
  </transmission>
  <link name="left_front1_wheel_link">
    <inertial>
      <origin rpy="0 0 0" xyz="0 0 0"/>
      <mass value="10"/>
      <inertia ixx="5" ixy="0.0" ixz="0.0" iyy="5" iyz="0.0" izz="5"/>
    </inertial>
    <!-- <visual>
        <geometry>
          <cylinder radius="0.5" length="0.5" />
        </geometry>
      </visual> -->
    <collision>
      <geometry>
        <cylinder length="0.1" radius="0.5"/>
      </geometry>
    </collision>
  </link>
  <gazebo reference="left_front1_wheel_link">
    <!--material>Gazebo/Red</material-->
    <mu1 value="0.7"/>
    <mu2 value="0.6"/>
    <kp value="7.5e+5"/>
    <kd value="0.001"/>
  </gazebo>
  <joint name="left_front2_wheel_joint" type="continuous">
    <origin rpy="-1.5707963267948966 0 0" xyz="1 1 0.5"/>
    <parent link="base_link"/>
    <child link="left_front2_wheel_link"/>
    <axis xyz="0 0 1"/>
  </joint>
  <transmission name="left_front2_wheel_trans" type="SimpleTransmission">
    <type>transmission_interface/SimpleTransmission</type>
    <actuator name="left_front2_wheel_motor">
      <mechanicalReduction>1</mechanicalReduction>
    </actuator>
    <joint name="left_front2_wheel_joint">
      <hardwareInterface>hardware_interface/VelocityJointInterface</hardwareInterface>
    </joint>
  </transmission>
  <link name="left_front2_wheel_link">
    <inertial>
      <origin rpy="0 0 0" xyz="0 0 0"/>
      <mass value="10"/>
      <inertia ixx="5" ixy="0.0" ixz="0.0" iyy="5" iyz="0.0" izz="5"/>
    </inertial>
    <!-- <visual>
        <geometry>
          <cylinder radius="0.5" length="0.5" />
        </geometry>
      </visual> -->
    <collision>
      <geometry>
        <cylinder length="0.1" radius="0.5"/>
      </geometry>
    </collision>
  </link>
  <gazebo reference="left_front2_wheel_link">
    <!--material>Gazebo/Red</material-->
    <mu1 value="0.7"/>
    <mu2 value="0.6"/>
    <kp value="7.5e+5"/>
    <kd value="0.001"/>
  </gazebo>
  <joint name="left_front3_wheel_joint" type="continuous">
    <origin rpy="-1.5707963267948966 0 0" xyz="1.5 1 0.5"/>
    <parent link="base_link"/>
    <child link="left_front3_wheel_link"/>
    <axis xyz="0 0 1"/>
  </joint>
  <transmission name="left_front3_wheel_trans" type="SimpleTransmission">
    <type>transmission_interface/SimpleTransmission</type>
    <actuator name="left_front3_wheel_motor">
      <mechanicalReduction>1</mechanicalReduction>
    </actuator>
    <joint name="left_front3_wheel_joint">
      <hardwareInterface>hardware_interface/VelocityJointInterface</hardwareInterface>
    </joint>
  </transmission>
  <link name="left_front3_wheel_link">
    <inertial>
      <origin rpy="0 0 0" xyz="0 0 0"/>
      <mass value="10"/>
      <inertia ixx="5" ixy="0.0" ixz="0.0" iyy="5" iyz="0.0" izz="5"/>
    </inertial>
    <!-- <visual>
        <geometry>
          <cylinder radius="0.5" length="0.5" />
        </geometry>
      </visual> -->
    <collision>
      <geometry>
        <cylinder length="0.1" radius="0.5"/>
      </geometry>
    </collision>
  </link>
  <gazebo reference="left_front3_wheel_link">
    <!--material>Gazebo/Red</material-->
    <mu1 value="0.7"/>
    <mu2 value="0.6"/>
    <kp value="7.5e+5"/>
    <kd value="0.001"/>
  </gazebo>
  <joint name="left_rear1_wheel_joint" type="continuous">
    <origin rpy="-1.5707963267948966 0 0" xyz="-0.5 1 0.5"/>
    <parent link="base_link"/>
    <child link="left_rear1_wheel_link"/>
    <axis xyz="0 0 1"/>
  </joint>
  <transmission name="left_rear1_wheel_trans" type="SimpleTransmission">
    <type>transmission_interface/SimpleTransmission</type>
    <actuator name="left_rear1_wheel_motor">
      <mechanicalReduction>1</mechanicalReduction>
    </actuator>
    <joint name="left_rear1_wheel_joint">
      <hardwareInterface>hardware_interface/VelocityJointInterface</hardwareInterface>
    </joint>
  </transmission>
  <link name="left_rear1_wheel_link">
    <inertial>
      <origin rpy="0 0 0" xyz="0 0 0"/>
      <mass value="10"/>
      <inertia ixx="5" ixy="0.0" ixz="0.0" iyy="5" iyz="0.0" izz="5"/>
    </inertial>
    <!-- <visual>
        <geometry>
          <cylinder radius="0.5" length="0.5" />
        </geometry>
      </visual> -->
    <collision>
      <geometry>
        <cylinder length="0.1" radius="0.5"/>
      </geometry>
    </collision>
  </link>
  <gazebo reference="left_rear1_wheel_link">
    <!--material>Gazebo/Red</material-->
    <mu1 value="0.7"/>
    <mu2 value="0.6"/>
    <kp value="7.5e+5"/>
    <kd value="0.001"/>
  </gazebo>
  <joint name="left_rear2_wheel_joint" type="continuous">
    <origin rpy="-1.5707963267948966 0 0" xyz="-1 1 0.5"/>
    <parent link="base_link"/>
    <child link="left_rear2_wheel_link"/>
    <axis xyz="0 0 1"/>
  </joint>
  <transmission name="left_rear2_wheel_trans" type="SimpleTransmission">
    <type>transmission_interface/SimpleTransmission</type>
    <actuator name="left_rear2_wheel_motor">
      <mechanicalReduction>1</mechanicalReduction>
    </actuator>
    <joint name="left_rear2_wheel_joint">
      <hardwareInterface>hardware_interface/VelocityJointInterface</hardwareInterface>
    </joint>
  </transmission>
  <link name="left_rear2_wheel_link">
    <inertial>
      <origin rpy="0 0 0" xyz="0 0 0"/>
      <mass value="10"/>
      <inertia ixx="5" ixy="0.0" ixz="0.0" iyy="5" iyz="0.0" izz="5"/>
    </inertial>
    <!-- <visual>
        <geometry>
          <cylinder radius="0.5" length="0.5" />
        </geometry>
      </visual> -->
    <collision>
      <geometry>
        <cylinder length="0.1" radius="0.5"/>
      </geometry>
    </collision>
  </link>
  <gazebo reference="left_rear2_wheel_link">
    <!--material>Gazebo/Red</material-->
    <mu1 value="0.7"/>
    <mu2 value="0.6"/>
    <kp value="7.5e+5"/>
    <kd value="0.001"/>
  </gazebo>
  <joint name="left_rear3_wheel_joint" type="continuous">
    <origin rpy="-1.5707963267948966 0 0" xyz="-1.5 1 0.5"/>
    <parent link="base_link"/>
    <child link="left_rear3_wheel_link"/>
    <axis xyz="0 0 1"/>
  </joint>
  <transmission name="left_rear3_wheel_trans" type="SimpleTransmission">
    <type>transmission_interface/SimpleTransmission</type>
    <actuator name="left_rear3_wheel_motor">
      <mechanicalReduction>1</mechanicalReduction>
    </actuator>
    <joint name="left_rear3_wheel_joint">
      <hardwareInterface>hardware_interface/VelocityJointInterface</hardwareInterface>
    </joint>
  </transmission>
  <link name="left_rear3_wheel_link">
    <inertial>
      <origin rpy="0 0 0" xyz="0 0 0"/>
      <mass value="10"/>
      <inertia ixx="5" ixy="0.0" ixz="0.0" iyy="5" iyz="0.0" izz="5"/>
    </inertial>
    <!-- <visual>
        <geometry>
          <cylinder radius="0.5" length="0.5" />
        </geometry>
      </visual> -->
    <collision>
      <geometry>
        <cylinder length="0.1" radius="0.5"/>
      </geometry>
    </collision>
  </link>
  <gazebo reference="left_rear3_wheel_link">
    <!--material>Gazebo/Red</material-->
    <mu1 value="0.7"/>
    <mu2 value="0.6"/>
    <kp value="7.5e+5"/>
    <kd value="0.001"/>
  </gazebo>
  <joint name="right_middle_wheel_joint" type="continuous">
    <origin rpy="-1.5707963267948966 0 0" xyz="0 -1 0.5"/>
    <parent link="base_link"/>
    <child link="right_middle_wheel_link"/>
    <axis xyz="0 0 1"/>
  </joint>
  <transmission name="right_middle_wheel_trans" type="SimpleTransmission">
    <type>transmission_interface/SimpleTransmission</type>
    <actuator name="right_middle_wheel_motor">
      <mechanicalReduction>1</mechanicalReduction>
    </actuator>
    <joint name="right_middle_wheel_joint">
      <hardwareInterface>hardware_interface/VelocityJointInterface</hardwareInterface>
    </joint>
  </transmission>
  <link name="right_middle_wheel_link">
    <inertial>
      <origin rpy="0 0 0" xyz="0 0 0"/>
      <mass value="10"/>
      <inertia ixx="5" ixy="0.0" ixz="0.0" iyy="5" iyz="0.0" izz="5"/>
    </inertial>
    <!-- <visual>
        <geometry>
          <cylinder radius="0.5" length="0.5" />
        </geometry>
      </visual> -->
    <collision>
      <geometry>
        <cylinder length="0.1" radius="0.5"/>
      </geometry>
    </collision>
  </link>
  <gazebo reference="right_middle_wheel_link">
    <!--material>Gazebo/Red</material-->
    <mu1 value="0.7"/>
    <mu2 value="0.6"/>
    <kp value="7.5e+5"/>
    <kd value="0.001"/>
  </gazebo>
  <joint name="right_front1_wheel_joint" type="continuous">
    <origin rpy="-1.5707963267948966 0 0" xyz="0.5 -1 0.5"/>
    <parent link="base_link"/>
    <child link="right_front1_wheel_link"/>
    <axis xyz="0 0 1"/>
  </joint>
  <transmission name="right_front1_wheel_trans" type="SimpleTransmission">
    <type>transmission_interface/SimpleTransmission</type>
    <actuator name="right_front1_wheel_motor">
      <mechanicalReduction>1</mechanicalReduction>
    </actuator>
    <joint name="right_front1_wheel_joint">
      <hardwareInterface>hardware_interface/VelocityJointInterface</hardwareInterface>
    </joint>
  </transmission>
  <link name="right_front1_wheel_link">
    <inertial>
      <origin rpy="0 0 0" xyz="0 0 0"/>
      <mass value="10"/>
      <inertia ixx="5" ixy="0.0" ixz="0.0" iyy="5" iyz="0.0" izz="5"/>
    </inertial>
    <!-- <visual>
        <geometry>
          <cylinder radius="0.5" length="0.5" />
        </geometry>
      </visual> -->
    <collision>
      <geometry>
        <cylinder length="0.1" radius="0.5"/>
      </geometry>
    </collision>
  </link>
  <gazebo reference="right_front1_wheel_link">
    <!--material>Gazebo/Red</material-->
    <mu1 value="0.7"/>
    <mu2 value="0.6"/>
    <kp value="7.5e+5"/>
    <kd value="0.001"/>
  </gazebo>
  <joint name="right_front2_wheel_joint" type="continuous">
    <origin rpy="-1.5707963267948966 0 0" xyz="1 -1 0.5"/>
    <parent link="base_link"/>
    <child link="right_front2_wheel_link"/>
    <axis xyz="0 0 1"/>
  </joint>
  <transmission name="right_front2_wheel_trans" type="SimpleTransmission">
    <type>transmission_interface/SimpleTransmission</type>
    <actuator name="right_front2_wheel_motor">
      <mechanicalReduction>1</mechanicalReduction>
    </actuator>
    <joint name="right_front2_wheel_joint">
      <hardwareInterface>hardware_interface/VelocityJointInterface</hardwareInterface>
    </joint>
  </transmission>
  <link name="right_front2_wheel_link">
    <inertial>
      <origin rpy="0 0 0" xyz="0 0 0"/>
      <mass value="10"/>
      <inertia ixx="5" ixy="0.0" ixz="0.0" iyy="5" iyz="0.0" izz="5"/>
    </inertial>
    <!-- <visual>
        <geometry>
          <cylinder radius="0.5" length="0.5" />
        </geometry>
      </visual> -->
    <collision>
      <geometry>
        <cylinder length="0.1" radius="0.5"/>
      </geometry>
    </collision>
  </link>
  <gazebo reference="right_front2_wheel_link">
    <!--material>Gazebo/Red</material-->
    <mu1 value="0.7"/>
    <mu2 value="0.6"/>
    <kp value="7.5e+5"/>
    <kd value="0.001"/>
  </gazebo>
  <joint name="right_front3_wheel_joint" type="continuous">
    <origin rpy="-1.5707963267948966 0 0" xyz="1.5 -1 0.5"/>
    <parent link="base_link"/>
    <child link="right_front3_wheel_link"/>
    <axis xyz="0 0 1"/>
  </joint>
  <transmission name="right_front3_wheel_trans" type="SimpleTransmission">
    <type>transmission_interface/SimpleTransmission</type>
    <actuator name="right_front3_wheel_motor">
      <mechanicalReduction>1</mechanicalReduction>
    </actuator>
    <joint name="right_front3_wheel_joint">
      <hardwareInterface>hardware_interface/VelocityJointInterface</hardwareInterface>
    </joint>
  </transmission>
  <link name="right_front3_wheel_link">
    <inertial>
      <origin rpy="0 0 0" xyz="0 0 0"/>
      <mass value="10"/>
      <inertia ixx="5" ixy="0.0" ixz="0.0" iyy="5" iyz="0.0" izz="5"/>
    </inertial>
    <!-- <visual>
        <geometry>
          <cylinder radius="0.5" length="0.5" />
        </geometry>
      </visual> -->
    <collision>
      <geometry>
        <cylinder length="0.1" radius="0.5"/>
      </geometry>
    </collision>
  </link>
  <gazebo reference="right_front3_wheel_link">
    <!--material>Gazebo/Red</material-->
    <mu1 value="0.7"/>
    <mu2 value="0.6"/>
    <kp value="7.5e+5"/>
    <kd value="0.001"/>
  </gazebo>
  <joint name="right_rear1_wheel_joint" type="continuous">
    <origin rpy="-1.5707963267948966 0 0" xyz="-0.5 -1 0.5"/>
    <parent link="base_link"/>
    <child link="right_rear1_wheel_link"/>
    <axis xyz="0 0 1"/>
  </joint>
  <transmission name="right_rear1_wheel_trans" type="SimpleTransmission">
    <type>transmission_interface/SimpleTransmission</type>
    <actuator name="right_rear1_wheel_motor">
      <mechanicalReduction>1</mechanicalReduction>
    </actuator>
    <joint name="right_rear1_wheel_joint">
      <hardwareInterface>hardware_interface/VelocityJointInterface</hardwareInterface>
    </joint>
  </transmission>
  <link name="right_rear1_wheel_link">
    <inertial>
      <origin rpy="0 0 0" xyz="0 0 0"/>
      <mass value="10"/>
      <inertia ixx="5" ixy="0.0" ixz="0.0" iyy="5" iyz="0.0" izz="5"/>
    </inertial>
    <!-- <visual>
        <geometry>
          <cylinder radius="0.5" length="0.5" />
        </geometry>
      </visual> -->
    <collision>
      <geometry>
        <cylinder length="0.1" radius="0.5"/>
      </geometry>
    </collision>
  </link>
  <gazebo reference="right_rear1_wheel_link">
    <!--material>Gazebo/Red</material-->
    <mu1 value="0.7"/>
    <mu2 value="0.6"/>
    <kp value="7.5e+5"/>
    <kd value="0.001"/>
  </gazebo>
  <joint name="right_rear2_wheel_joint" type="continuous">
    <origin rpy="-1.5707963267948966 0 0" xyz="-1 -1 0.5"/>
    <parent link="base_link"/>
    <child link="right_rear2_wheel_link"/>
    <axis xyz="0 0 1"/>
  </joint>
  <transmission name="right_rear2_wheel_trans" type="SimpleTransmission">
    <type>transmission_interface/SimpleTransmission</type>
    <actuator name="right_rear2_wheel_motor">
      <mechanicalReduction>1</mechanicalReduction>
    </actuator>
    <joint name="right_rear2_wheel_joint">
      <hardwareInterface>hardware_interface/VelocityJointInterface</hardwareInterface>
    </joint>
  </transmission>
  <link name="right_rear2_wheel_link">
    <inertial>
      <origin rpy="0 0 0" xyz="0 0 0"/>
      <mass value="10"/>
      <inertia ixx="5" ixy="0.0" ixz="0.0" iyy="5" iyz="0.0" izz="5"/>
    </inertial>
    <!-- <visual>
        <geometry>
          <cylinder radius="0.5" length="0.5" />
        </geometry>
      </visual> -->
    <collision>
      <geometry>
        <cylinder length="0.1" radius="0.5"/>
      </geometry>
    </collision>
  </link>
  <gazebo reference="right_rear2_wheel_link">
    <!--material>Gazebo/Red</material-->
    <mu1 value="0.7"/>
    <mu2 value="0.6"/>
    <kp value="7.5e+5"/>
    <kd value="0.001"/>
  </gazebo>
  <joint name="right_rear3_wheel_joint" type="continuous">
    <origin rpy="-1.5707963267948966 0 0" xyz="-1.5 -1 0.5"/>
    <parent link="base_link"/>
    <child link="right_rear3_wheel_link"/>
    <axis xyz="0 0 1"/>
  </joint>
  <transmission name="right_rear3_wheel_trans" type="SimpleTransmission">
    <type>transmission_interface/SimpleTransmission</type>
    <actuator name="right_rear3_wheel_motor">
      <mechanicalReduction>1</mechanicalReduction>
    </actuator>
    <joint name="right_rear3_wheel_joint">
      <hardwareInterface>hardware_interface/VelocityJointInterface</hardwareInterface>
    </joint>
  </transmission>
  <link name="right_rear3_wheel_link">
    <inertial>
      <origin rpy="0 0 0" xyz="0 0 0"/>
      <mass value="10"/>
      <inertia ixx="5" ixy="0.0" ixz="0.0" iyy="5" iyz="0.0" izz="5"/>
    </inertial>
    <!-- <visual>
        <geometry>
          <cylinder radius="0.5" length="0.5" />
        </geometry>
      </visual> -->
    <collision>
      <geometry>
        <cylinder length="0.1" radius="0.5"/>
      </geometry>
    </collision>
  </link>
  <gazebo reference="right_rear3_wheel_link">
    <!--material>Gazebo/Red</material-->
    <mu1 value="0.7"/>
    <mu2 value="0.6"/>
    <kp value="7.5e+5"/>
    <kd value="0.001"/>
  </gazebo>
  <gazebo>
    <plugin filename="libgazebo_ros_control.so" name="gazebo_ros_control"/>
    <!-- <robotNamespace>/ic120</robotNamespace>
    </plugin> -->
  </gazebo>
</robot>

