<?xml version="1.0" ?>
<!-- =================================================================================== -->
<!-- |    This document was autogenerated by xacro from zx135u.xacro                   | -->
<!-- |    EDITING THIS FILE BY HAND IS NOT RECOMMENDED                                 | -->
<!-- =================================================================================== -->
<robot name="zx135u" xmlns:xacro="http://ros.org/wiki/xacro">
  <!-- Inertia is calculated as slender rod in https://en.wikipedia.org/wiki/List_of_moments_of_inertia#List_of_3D_inertia_tensors -->
  <link name="base_link">
    <visual>
      <geometry>
        <mesh filename="package://excavator_model/mesh/meshbody39_rviz.stl"/>
      </geometry>
      <origin rpy="0 0 0" xyz="0 0 0"/>
      <material name="Gray">
        <color rgba="0.7 0.7 0.7 1.0"/>
      </material>
    </visual>
    <inertial>
      <mass value="2.0"/>
      <inertia ixx="1" ixy="0.0" ixz="0.0" iyy="1" iyz="0.0" izz="1"/>
    </inertial>
  </link>
  <joint name="left_front_wheel_joint" type="continuous">
    <origin rpy="-1.5707963267948966 0 0" xyz="0 1 0.6"/>
    <parent link="base_link"/>
    <child link="left_front_wheel_link"/>
    <axis xyz="0 0 1"/>
  </joint>
  <transmission name="left_front_wheel_trans" type="SimpleTransmission">
    <type>transmission_interface/SimpleTransmission</type>
    <actuator name="left_front_wheel_motor">
      <mechanicalReduction>1</mechanicalReduction>
    </actuator>
    <joint name="left_front_wheel_joint">
      <hardwareInterface>hardware_interface/VelocityJointInterface</hardwareInterface>
    </joint>
  </transmission>
  <link name="left_front_wheel_link">
    <inertial>
      <origin rpy="0 0 0" xyz="0 0 0"/>
      <mass value="0.1"/>
      <inertia ixx="0.0001" ixy="0.0" ixz="0.0" iyy="0.0001" iyz="0.0" izz="0.0001"/>
    </inertial>
    <visual>
      <geometry>
        <cylinder length="0.001" radius="0.001"/>
      </geometry>
      <!--material name="red"/-->
    </visual>
    <collision>
      <geometry>
        <cylinder length="0.6" radius="0.6"/>
      </geometry>
    </collision>
  </link>
  <gazebo reference="left_front_wheel_link">
    <!--material>Gazebo/Red</material-->
    <mu1 value="2.5"/>
    <mu2 value="2.5"/>
    <kp value="50000"/>
    <kd value="10"/>
  </gazebo>
  <joint name="left_middle_wheel_joint" type="continuous">
    <origin rpy="-1.5707963267948966 0 0" xyz="-1.5 1 0.6"/>
    <parent link="base_link"/>
    <child link="left_middle_wheel_link"/>
    <axis xyz="0 0 1"/>
  </joint>
  <transmission name="left_middle_wheel_trans" type="SimpleTransmission">
    <type>transmission_interface/SimpleTransmission</type>
    <actuator name="left_middle_wheel_motor">
      <mechanicalReduction>1</mechanicalReduction>
    </actuator>
    <joint name="left_middle_wheel_joint">
      <hardwareInterface>hardware_interface/VelocityJointInterface</hardwareInterface>
    </joint>
  </transmission>
  <link name="left_middle_wheel_link">
    <inertial>
      <origin rpy="0 0 0" xyz="0 0 0"/>
      <mass value="0.1"/>
      <inertia ixx="0.0001" ixy="0.0" ixz="0.0" iyy="0.0001" iyz="0.0" izz="0.0001"/>
    </inertial>
    <visual>
      <geometry>
        <cylinder length="0.001" radius="0.001"/>
      </geometry>
      <!--material name="red"/-->
    </visual>
    <collision>
      <geometry>
        <cylinder length="0.6" radius="0.6"/>
      </geometry>
    </collision>
  </link>
  <gazebo reference="left_middle_wheel_link">
    <!--material>Gazebo/Red</material-->
    <mu1 value="2.5"/>
    <mu2 value="2.5"/>
    <kp value="50000"/>
    <kd value="10"/>
  </gazebo>
  <joint name="left_rear_wheel_joint" type="continuous">
    <origin rpy="-1.5707963267948966 0 0" xyz="1.5 1 0.6"/>
    <parent link="base_link"/>
    <child link="left_rear_wheel_link"/>
    <axis xyz="0 0 1"/>
  </joint>
  <transmission name="left_rear_wheel_trans" type="SimpleTransmission">
    <type>transmission_interface/SimpleTransmission</type>
    <actuator name="left_rear_wheel_motor">
      <mechanicalReduction>1</mechanicalReduction>
    </actuator>
    <joint name="left_rear_wheel_joint">
      <hardwareInterface>hardware_interface/VelocityJointInterface</hardwareInterface>
    </joint>
  </transmission>
  <link name="left_rear_wheel_link">
    <inertial>
      <origin rpy="0 0 0" xyz="0 0 0"/>
      <mass value="0.1"/>
      <inertia ixx="0.0001" ixy="0.0" ixz="0.0" iyy="0.0001" iyz="0.0" izz="0.0001"/>
    </inertial>
    <visual>
      <geometry>
        <cylinder length="0.001" radius="0.001"/>
      </geometry>
      <!--material name="red"/-->
    </visual>
    <collision>
      <geometry>
        <cylinder length="0.6" radius="0.6"/>
      </geometry>
    </collision>
  </link>
  <gazebo reference="left_rear_wheel_link">
    <!--material>Gazebo/Red</material-->
    <mu1 value="2.5"/>
    <mu2 value="2.5"/>
    <kp value="50000"/>
    <kd value="10"/>
  </gazebo>
  <joint name="right_front_wheel_joint" type="continuous">
    <origin rpy="-1.5707963267948966 0 0" xyz="0 -1 0.6"/>
    <parent link="base_link"/>
    <child link="right_front_wheel_link"/>
    <axis xyz="0 0 1"/>
  </joint>
  <transmission name="right_front_wheel_trans" type="SimpleTransmission">
    <type>transmission_interface/SimpleTransmission</type>
    <actuator name="right_front_wheel_motor">
      <mechanicalReduction>1</mechanicalReduction>
    </actuator>
    <joint name="right_front_wheel_joint">
      <hardwareInterface>hardware_interface/VelocityJointInterface</hardwareInterface>
    </joint>
  </transmission>
  <link name="right_front_wheel_link">
    <inertial>
      <origin rpy="0 0 0" xyz="0 0 0"/>
      <mass value="0.1"/>
      <inertia ixx="0.0001" ixy="0.0" ixz="0.0" iyy="0.0001" iyz="0.0" izz="0.0001"/>
    </inertial>
    <visual>
      <geometry>
        <cylinder length="0.001" radius="0.001"/>
      </geometry>
      <!--material name="red"/-->
    </visual>
    <collision>
      <geometry>
        <cylinder length="0.6" radius="0.6"/>
      </geometry>
    </collision>
  </link>
  <gazebo reference="right_front_wheel_link">
    <!--material>Gazebo/Red</material-->
    <mu1 value="2.5"/>
    <mu2 value="2.5"/>
    <kp value="50000"/>
    <kd value="10"/>
  </gazebo>
  <joint name="right_middle_wheel_joint" type="continuous">
    <origin rpy="-1.5707963267948966 0 0" xyz="-1.5 -1 0.6"/>
    <parent link="base_link"/>
    <child link="right_middle_wheel_link"/>
    <axis xyz="0 0 1"/>
  </joint>
  <transmission name="right_middle_wheel_trans" type="SimpleTransmission">
    <type>transmission_interface/SimpleTransmission</type>
    <actuator name="right_middle_wheel_motor">
      <mechanicalReduction>1</mechanicalReduction>
    </actuator>
    <joint name="right_middle_wheel_joint">
      <hardwareInterface>hardware_interface/VelocityJointInterface</hardwareInterface>
    </joint>
  </transmission>
  <link name="right_middle_wheel_link">
    <inertial>
      <origin rpy="0 0 0" xyz="0 0 0"/>
      <mass value="0.1"/>
      <inertia ixx="0.0001" ixy="0.0" ixz="0.0" iyy="0.0001" iyz="0.0" izz="0.0001"/>
    </inertial>
    <visual>
      <geometry>
        <cylinder length="0.001" radius="0.001"/>
      </geometry>
      <!--material name="red"/-->
    </visual>
    <collision>
      <geometry>
        <cylinder length="0.6" radius="0.6"/>
      </geometry>
    </collision>
  </link>
  <gazebo reference="right_middle_wheel_link">
    <!--material>Gazebo/Red</material-->
    <mu1 value="2.5"/>
    <mu2 value="2.5"/>
    <kp value="50000"/>
    <kd value="10"/>
  </gazebo>
  <joint name="right_rear_wheel_joint" type="continuous">
    <origin rpy="-1.5707963267948966 0 0" xyz="1.5 -1 0.6"/>
    <parent link="base_link"/>
    <child link="right_rear_wheel_link"/>
    <axis xyz="0 0 1"/>
  </joint>
  <transmission name="right_rear_wheel_trans" type="SimpleTransmission">
    <type>transmission_interface/SimpleTransmission</type>
    <actuator name="right_rear_wheel_motor">
      <mechanicalReduction>1</mechanicalReduction>
    </actuator>
    <joint name="right_rear_wheel_joint">
      <hardwareInterface>hardware_interface/VelocityJointInterface</hardwareInterface>
    </joint>
  </transmission>
  <link name="right_rear_wheel_link">
    <inertial>
      <origin rpy="0 0 0" xyz="0 0 0"/>
      <mass value="0.1"/>
      <inertia ixx="0.0001" ixy="0.0" ixz="0.0" iyy="0.0001" iyz="0.0" izz="0.0001"/>
    </inertial>
    <visual>
      <geometry>
        <cylinder length="0.001" radius="0.001"/>
      </geometry>
      <!--material name="red"/-->
    </visual>
    <collision>
      <geometry>
        <cylinder length="0.6" radius="0.6"/>
      </geometry>
    </collision>
  </link>
  <gazebo reference="right_rear_wheel_link">
    <!--material>Gazebo/Red</material-->
    <mu1 value="2.5"/>
    <mu2 value="2.5"/>
    <kp value="50000"/>
    <kd value="10"/>
  </gazebo>
  <!-- Track Model and Joint Definition-->
  <link name="track_link">
    <visual>
      <geometry>
        <mesh filename="package://excavator_model/mesh/meshbody38_rviz.stl"/>
      </geometry>
      <origin rpy="0 0 0" xyz="0 0 0"/>
      <material name="Black">
        <color rgba="0.0 0.0 0.0 1.0"/>
      </material>
    </visual>
    <inertial>
      <mass value="1"/>
      <inertia ixx="1" ixy="0.0" ixz="0.0" iyy="1" iyz="0.0" izz="1"/>
    </inertial>
  </link>
  <joint name="track_joint" type="fixed">
    <parent link="base_link"/>
    <child link="track_link"/>
    <origin xyz="0 0 0"/>
  </joint>
  <!-- Rotator Model and Joint Definition-->
  <link name="rotator_link">
    <visual>
      <geometry>
        <mesh filename="package://excavator_model/mesh/meshbody1_rviz.stl"/>
      </geometry>
      <origin rpy="0 0 0" xyz="0 0 0"/>
      <material name="Gray">
        <color rgba="0.7 0.7 0.7 1.0"/>
      </material>
    </visual>
    <inertial>
      <mass value="1"/>
      <!-- inertia ixx="${(boom_mass*4.6*4.6)/3}" ixy="0.0" ixz="0.0" iyy="0.0" iyz="0.0" izz="${(boom_mass*4.6*4.6)/3}"/ -->
      <inertia ixx="1" ixy="0.0" ixz="0.0" iyy="1" iyz="0.0" izz="1"/>
    </inertial>
  </link>
  <joint name="rotator_joint" type="continuous">
    <parent link="base_link"/>
    <child link="rotator_link"/>
    <axis xyz="0 0 1"/>
    <origin xyz="0 0 0.643"/>
    <!-- limit effort="100" lower="${-70/180*PI}" upper="${44/180*PI}" velocity="5"/-->
  </joint>
  <gazebo reference="rotator_link">
    <turnGravityOff>True</turnGravityOff>
  </gazebo>
  <!-- upper Model and Joint Definition-->
  <link name="upper_link">
    <visual>
      <geometry>
        <mesh filename="package://excavator_model/mesh/meshbody12-18_rviz.stl"/>
      </geometry>
      <origin rpy="0 0 0" xyz="0 0 0"/>
      <material name="Orange">
        <color rgba="0.97 0.41 0.05 1"/>
      </material>
    </visual>
    <inertial>
      <mass value="1"/>
      <inertia ixx="1" ixy="0.0" ixz="0.0" iyy="1" iyz="0.0" izz="1"/>
    </inertial>
  </link>
  <joint name="upper_joint" type="fixed">
    <parent link="rotator_link"/>
    <child link="upper_link"/>
    <origin xyz="0 0 0.249"/>
  </joint>
  <!-- cabin Model and Joint Definition-->
  <link name="cabin_link">
    <visual>
      <geometry>
        <mesh filename="package://excavator_model/mesh/meshbody10_rviz.stl"/>
      </geometry>
      <origin rpy="0 0 0" xyz="0 0 0"/>
      <material name="Black">
        <color rgba="0 0 0 1.0"/>
      </material>
    </visual>
    <visual>
      <geometry>
        <mesh filename="package://excavator_model/mesh/meshbody2-8_rviz.stl"/>
      </geometry>
      <origin rpy="0 0 0" xyz="0 0 0"/>
      <material name="White">
        <color rgba="1.0 1.0 1.0 1.0"/>
      </material>
    </visual>
  </link>
  <joint name="cabin_joint" type="fixed">
    <parent link="upper_link"/>
    <child link="cabin_link"/>
    <origin xyz="0 0 0.2"/>
  </joint>
  <!-- boom Model and Joint Definition-->
  <link name="boom_link">
    <visual>
      <geometry>
        <mesh filename="package://excavator_model/mesh/meshbody19_rviz.stl" scale="1.115 1.115 1.115"/>
      </geometry>
      <origin rpy="0 -1.5457963267500001 0" xyz="0 0 0"/>
      <material name="Orange">
        <color rgba="0.97 0.41 0.05 1"/>
      </material>
    </visual>
    <inertial>
      <mass value="1"/>
      <inertia ixx="7.053333333333332" ixy="0.0" ixz="0.0" iyy="0.0" iyz="0.0" izz="7.053333333333332"/>
    </inertial>
  </link>
  <joint name="boom_joint" type="revolute">
    <parent link="upper_link"/>
    <child link="boom_link"/>
    <axis xyz="0 1 0"/>
    <origin rpy="0 1.57079632675 0" xyz="0.14 -0.16 0.532"/>
    <limit effort="1" lower="-1.2217304763611112" upper="0.7679448708555555" velocity="0.5"/>
  </joint>
  <gazebo reference="boom_link">
    <turnGravityOff>True</turnGravityOff>
  </gazebo>
  <!-- arm Model and Joint Definition-->
  <link name="arm_link">
    <visual>
      <geometry>
        <mesh filename="package://excavator_model/mesh/meshbody26_rviz.stl" scale="1.17 1.17 1.17"/>
      </geometry>
      <origin rpy="0 2.0843951023333336 0" xyz="-0.3 0 -0.55"/>
      <material name="Orange">
        <color rgba="0.97 0.41 0.05 1"/>
      </material>
    </visual>
    <inertial>
      <mass value="1"/>
      <inertia ixx="7.053333333333332" ixy="0.0" ixz="0.0" iyy="0.0" iyz="0.0" izz="7.053333333333332"/>
    </inertial>
  </link>
  <joint name="arm_joint" type="revolute">
    <parent link="boom_link"/>
    <child link="arm_link"/>
    <axis xyz="0 1 0"/>
    <origin rpy="0 0 0" xyz="0 0 4.6"/>
    <limit effort="1" lower="0.5235987755833333" upper="2.6529004629555555" velocity="0.5"/>
  </joint>
  <gazebo reference="arm_link">
    <turnGravityOff>True</turnGravityOff>
  </gazebo>
  <!-- backet Model and Joint Definition-->
  <link name="backet_link">
    <visual>
      <geometry>
        <mesh filename="package://excavator_model/mesh/meshbody24_rviz.stl" scale="0.99 0.99 0.99"/>
      </geometry>
      <origin rpy="0 -0.4415987755833333 0" xyz="-0.1 0 -0.05"/>
      <material name="Orange">
        <color rgba="0.97 0.41 0.05 1"/>
      </material>
    </visual>
    <inertial>
      <mass value="1"/>
      <inertia ixx="7.053333333333332" ixy="0.0" ixz="0.0" iyy="0.0" iyz="0.0" izz="7.053333333333332"/>
    </inertial>
  </link>
  <joint name="backet_joint" type="revolute">
    <parent link="arm_link"/>
    <child link="backet_link"/>
    <axis xyz="0 1 0"/>
    <origin rpy="0 0 0" xyz="0 0 2.519"/>
    <limit effort="1" lower="-0.5759586531416666" upper="2.4958208302805556" velocity="0.5"/>
  </joint>
  <!-- backet end Model and Joint Definition-->
  <link name="backet_end_link">
    <visual>
      <origin rpy="0 0 0" xyz="0 0 0"/>
      <geometry>
        <box size="0.001 0.001 0.001"/>
      </geometry>
      <material name="red"/>
    </visual>
    <inertial>
      <origin xyz="0 0 0"/>
      <mass value="1.0e-03"/>
      <inertia ixx="1.0e-03" ixy="0.0" ixz="0.0" iyy="1.0e-03" iyz="0.0" izz="1.0e-03"/>
    </inertial>
  </link>
  <joint name="backet_end_joint" type="revolute">
    <parent link="backet_link"/>
    <child link="backet_end_link"/>
    <axis xyz="1 0 0"/>
    <origin rpy="0 0 0" xyz="0 0 1.23"/>
    <limit effort="1" lower="-3.14" upper="3.14" velocity="0.5"/>
  </joint>
  <gazebo reference="backet_link">
    <turnGravityOff>True</turnGravityOff>
  </gazebo>
  <transmission name="rotator_trans">
    <type>transmission_interface/SimpleTransmission</type>
    <joint name="rotator_joint">
      <hardwareInterface>hardware_interface/PositionJointInterface</hardwareInterface>
    </joint>
    <actuator name="rotator_motor">
      <hardwareInterface>hardware_interface/PositionJointInterface</hardwareInterface>
      <mechanicalReduction>1</mechanicalReduction>
    </actuator>
  </transmission>
  <transmission name="boom_trans">
    <type>transmission_interface/SimpleTransmission</type>
    <joint name="boom_joint">
      <hardwareInterface>hardware_interface/PositionJointInterface</hardwareInterface>
    </joint>
    <actuator name="boom_motor">
      <hardwareInterface>hardware_interface/PositionJointInterface</hardwareInterface>
      <mechanicalReduction>1</mechanicalReduction>
    </actuator>
  </transmission>
  <transmission name="arm_trans">
    <type>transmission_interface/SimpleTransmission</type>
    <joint name="arm_joint">
      <hardwareInterface>hardware_interface/PositionJointInterface</hardwareInterface>
    </joint>
    <actuator name="arm_motor">
      <hardwareInterface>hardware_interface/PositionJointInterface</hardwareInterface>
      <mechanicalReduction>1</mechanicalReduction>
    </actuator>
  </transmission>
  <transmission name="backet_trans">
    <type>transmission_interface/SimpleTransmission</type>
    <joint name="backet_joint">
      <hardwareInterface>hardware_interface/PositionJointInterface</hardwareInterface>
    </joint>
    <actuator name="backet_motor">
      <hardwareInterface>hardware_interface/PositionJointInterface</hardwareInterface>
      <mechanicalReduction>1</mechanicalReduction>
    </actuator>
  </transmission>
  <transmission name="dummy_trans1">
    <type>transmission_interface/SimpleTransmission</type>
    <joint name="backet_end_joint">
      <hardwareInterface>hardware_interface/PositionJointInterface</hardwareInterface>
    </joint>
    <actuator name="dummy_motor1">
      <hardwareInterface>hardware_interface/PositionJointInterface</hardwareInterface>
      <mechanicalReduction>1</mechanicalReduction>
    </actuator>
  </transmission>
  <gazebo>
    <plugin filename="libgazebo_ros_control.so" name="gazebo_ros_control">
      <robotNamespace>/zx135u</robotNamespace>
      <robotSimType>gazebo_ros_control/DefaultRobotHWSim</robotSimType>
      <legacyModeNS>true</legacyModeNS>
    </plugin>
  </gazebo>
</robot>

