<?xml version="1.0" encoding="utf-8"?>
<!-- =================================================================================== -->
<!-- |    This document was autogenerated by xacro from zx120-unity.xacro              | -->
<!-- |    EDITING THIS FILE BY HAND IS NOT RECOMMENDED                                 | -->
<!-- =================================================================================== -->
<robot name="zx120">
  <!-- ros_control plugin -->
  <!-- Import Rviz colors -->
  <!-- <xacro:include filename="$(find zx120_description)/urdf/materials.xacro" /> -->


  <!-- Base Link -->
  <link name="base_link">
    <visual>
      <geometry>
        <mesh filename="package://zx120_description/meshes/zx120-crawler.dae"/>
      </geometry>
    </visual>
    <inertial>
      <origin rpy="0 0 0" xyz="-0.155869 0 0.358402"/>
      <mass value="2.0"/>
      <inertia ixx="1.0" ixy="0.0" ixz="0.0" iyy="1.0" iyz="0.0" izz="1.0"/>
    </inertial>
  </link>
  <joint name="left_front_wheel_joint" type="continuous">
    <origin rpy="-1.57079632679 0 0" xyz="1.5 1 0.3"/>
    <parent link="base_link"/>
    <child link="left_front_wheel_link"/>
    <axis xyz="0 0 1"/>
  </joint>

  <link name="left_front_wheel_link">
    <inertial>
      <origin rpy="0 0 0" xyz="0 0 0"/>
      <mass value="0.1"/>
      <inertia ixx="0.0001" ixy="0.0" ixz="0.0" iyy="0.0001" iyz="0.0" izz="0.0001"/>
    </inertial>
    <visual>
      <geometry>
        <cylinder length="0.001" radius="0.001"/>
      </geometry>
    </visual>
    <collision>
      <geometry>
        <cylinder length="0.6" radius="0.3"/>
      </geometry>
    </collision>
  </link>

  <joint name="left_middle_wheel_joint" type="continuous">
    <origin rpy="-1.57079632679 0 0" xyz="0 1 0.3"/>
    <parent link="base_link"/>
    <child link="left_middle_wheel_link"/>
    <axis xyz="0 0 1"/>
  </joint>

  <link name="left_middle_wheel_link">
    <inertial>
      <origin rpy="0 0 0" xyz="0 0 0"/>
      <mass value="0.1"/>
      <inertia ixx="0.0001" ixy="0.0" ixz="0.0" iyy="0.0001" iyz="0.0" izz="0.0001"/>
    </inertial>
    <visual>
      <geometry>
        <cylinder length="0.001" radius="0.001"/>
      </geometry>
    </visual>
    <collision>
      <geometry>
        <cylinder length="0.6" radius="0.3"/>
      </geometry>
    </collision>
  </link>

  <joint name="left_rear_wheel_joint" type="continuous">
    <origin rpy="-1.57079632679 0 0" xyz="-1.5 1 0.3"/>
    <parent link="base_link"/>
    <child link="left_rear_wheel_link"/>
    <axis xyz="0 0 1"/>
  </joint>

  <link name="left_rear_wheel_link">
    <inertial>
      <origin rpy="0 0 0" xyz="0 0 0"/>
      <mass value="0.1"/>
      <inertia ixx="0.0001" ixy="0.0" ixz="0.0" iyy="0.0001" iyz="0.0" izz="0.0001"/>
    </inertial>
    <visual>
      <geometry>
        <cylinder length="0.001" radius="0.001"/>
      </geometry>
    </visual>
    <collision>
      <geometry>
        <cylinder length="0.6" radius="0.3"/>
      </geometry>
    </collision>
  </link>

  <joint name="right_front_wheel_joint" type="continuous">
    <origin rpy="-1.57079632679 0 0" xyz="1.5 -1 0.3"/>
    <parent link="base_link"/>
    <child link="right_front_wheel_link"/>
    <axis xyz="0 0 1"/>
  </joint>

  <link name="right_front_wheel_link">
    <inertial>
      <origin rpy="0 0 0" xyz="0 0 0"/>
      <mass value="0.1"/>
      <inertia ixx="0.0001" ixy="0.0" ixz="0.0" iyy="0.0001" iyz="0.0" izz="0.0001"/>
    </inertial>
    <visual>
      <geometry>
        <cylinder length="0.001" radius="0.001"/>
      </geometry>
    </visual>
    <collision>
      <geometry>
        <cylinder length="0.6" radius="0.3"/>
      </geometry>
    </collision>
  </link>

  <joint name="right_middle_wheel_joint" type="continuous">
    <origin rpy="-1.57079632679 0 0" xyz="0 -1 0.3"/>
    <parent link="base_link"/>
    <child link="right_middle_wheel_link"/>
    <axis xyz="0 0 1"/>
  </joint>

  <link name="right_middle_wheel_link">
    <inertial>
      <origin rpy="0 0 0" xyz="0 0 0"/>
      <mass value="0.1"/>
      <inertia ixx="0.0001" ixy="0.0" ixz="0.0" iyy="0.0001" iyz="0.0" izz="0.0001"/>
    </inertial>
    <visual>
      <geometry>
        <cylinder length="0.001" radius="0.001"/>
      </geometry>
    </visual>
    <collision>
      <geometry>
        <cylinder length="0.6" radius="0.3"/>
      </geometry>
    </collision>
  </link>

  <joint name="right_rear_wheel_joint" type="continuous">
    <origin rpy="-1.57079632679 0 0" xyz="-1.5 -1 0.3"/>
    <parent link="base_link"/>
    <child link="right_rear_wheel_link"/>
    <axis xyz="0 0 1"/>
  </joint>

  <link name="right_rear_wheel_link">
    <inertial>
      <origin rpy="0 0 0" xyz="0 0 0"/>
      <mass value="0.1"/>
      <inertia ixx="0.0001" ixy="0.0" ixz="0.0" iyy="0.0001" iyz="0.0" izz="0.0001"/>
    </inertial>
    <visual>
      <geometry>
        <cylinder length="0.001" radius="0.001"/>
      </geometry>
    </visual>
    <collision>
      <geometry>
        <cylinder length="0.6" radius="0.3"/>
      </geometry>
    </collision>
  </link>


  <!-- body axis -->
  <joint name="swing_joint" type="continuous">
    <origin xyz="0 0 0.643"/>
    <axis xyz="0 0 2"/>
    <parent link="base_link"/>
    <child link="body_link"/>
  </joint>

  <link name="body_link">
    <visual>
      <origin xyz="0 0 0.35"/>
      <geometry>
        <mesh filename="package://zx120_description/meshes/zx120-body.dae"/>
      </geometry>
    </visual>
    <collision>
      <origin xyz="0 0 0.35"/>
      <geometry>
        <mesh filename="package://zx120_description/meshes/zx120-body.dae"/>
      </geometry>
    </collision>
    <inertial>
      <origin rpy="0 0 0" xyz="-0.501522 0 1.191169"/>
      <mass value="2"/>
      <inertia ixx="1.0" ixy="0.0" ixz="0.0" iyy="1.0" iyz="0.0" izz="1.0"/>
    </inertial>
  </link>


  <!-- boom axis -->
  <joint name="boom_joint" type="revolute">
    <origin rpy="0 1.57079632675 0" xyz="0.14 -0.16 0.781"/>
    <axis xyz="0 1 0"/>
    <parent link="body_link"/>
    <child link="boom_link"/>
    <limit effort="500" lower="-1.2217304764" upper="0.767944870878" velocity="6.159937255"/>
  </joint>
  <link name="boom_link">
    <visual>
      <origin rpy="0 -1.18079632675 0" xyz="0 0 0"/>
      <geometry>
        <mesh filename="package://zx120_description/meshes/zx120-boom.dae"/>
      </geometry>
    </visual>
    <collision>
      <origin rpy="0 -1.18079632675 0" xyz="0 0 0"/>
      <geometry>
        <mesh filename="package://zx120_description/meshes/zx120-boom.dae"/>
      </geometry>
    </collision>
    <inertial>
      <origin rpy="0 0 0" xyz="2.091062 0.055029 0.975556"/>
      <mass value="1"/>
      <inertia ixx="7.05333333333" ixy="0.0" ixz="0.0" iyy="0.0" iyz="0.0" izz="7.05333333333"/>
    </inertial>
  </link>

  <joint name="boom_cylinder_joint" type="revolute">
    <origin rpy="0 1.57079632675 0" xyz="0.14 -0.16 0.781"/>
    <axis xyz="0 1 0"/>
    <parent link="body_link"/>
    <child link="boom_cylinder_link"/>
    <limit effort="500" lower="-1.2217304764" upper="0.767944870878" velocity="6.159937255"/>
  </joint>

  <link name="boom_cylinder_link">
    <visual>
      <origin xyz="0 0 0"/>
      <geometry>
        <mesh filename="package://meshes/zx120-boom-cyl1.dae"/>
      </geometry>
    </visual>
    <collision>
      <origin xyz="0 0 0"/>
      <geometry>
        <mesh filename="package://meshes/zx120-boom-cyl1.dae"/>
      </geometry>
    </collision>
    <inertial>
      <origin rpy="0 0 0" xyz="0.241225 0.000050 0.577034"/>
      <mass value="0.03"/>
      <inertia ixx="1.0" ixy="0.0" ixz="0.0" iyy="1.0" iyz="0.0" izz="1.0"/>
    </inertial>
  </link>

  <joint name="boom_rod_joint" type="prismatic">
    <origin xyz="0 0 0"/>
    <axis xyz="0.802033 0 1.847495"/>
    <parent link="boom_cylinder_link"/>
    <child link="boom_rod_link"/>
    <limit effort="500" lower="-2" upper="2" velocity="6.159937255"/>
    <mimic joint="joint2" multiplier="-0.319672131148"/>
  </joint>

  <link name="boom_rod_link">
    <visual>
      <origin xyz="0 0 0"/>
      <geometry>
        <mesh filename="package://meshes/zx120-boom-cyl2.dae"/>
      </geometry>
    </visual>
    <collision>
      <origin xyz="0 0 0"/>
      <geometry>
        <mesh filename="package://meshes/zx120-boom-cyl2.dae"/>
      </geometry>
    </collision>
    <inertial>
      <origin rpy="0 0 0" xyz="0.558044 0.000050 1.286359"/>
      <mass value="0.03"/>
      <inertia ixx="1.0" ixy="0.0" ixz="0.0" iyy="1.0" iyz="0.0" izz="1.0"/>
    </inertial>
  </link>



  <!-- arm axis -->
  <joint name="arm_joint" type="revolute">
    <origin rpy="0 0 0" xyz="0 0 4.6"/>
    <axis xyz="0 1 0"/>
    <parent link="boom_link"/>
    <child link="arm_link"/>
    <limit effort="500" lower="0.523598775598" upper="2.65290046303" velocity="6.159937255"/>
  </joint>
  <link name="arm_link">
    <visual>
      <origin rpy="0 3.2915926535 0" xyz="0 0 0"/>
      <geometry>
        <mesh filename="package://zx120_description/meshes/zx120-arm.dae"/>
      </geometry>
    </visual>
    <collision>
      <origin rpy="0 3.2915926535 0" xyz="0 0 0"/>
      <geometry>
        <mesh filename="package://zx120_description/meshes/zx120-arm.dae"/>
      </geometry>
    </collision>
    <inertial>
      <origin rpy="0 0 0" xyz="0.305996 0.000026 -0.912806"/>
      <mass value="1"/>
      <inertia ixx="7.05333333333" ixy="0.0" ixz="0.0" iyy="0.0" iyz="0.0" izz="7.05333333333"/>
    </inertial>
  </link>

  <joint name="arm_cylinder_joint" type="fixed">
    <origin xyz="2.053030 0 1.991444"  rpy="0 -0.156207 0"/>
    <axis xyz="0 1 0"/>
    <parent link="boom_link"/>
    <child link="arm_cylinder_link"/>
  </joint>

  <link name="arm_cylinder_link">
    <visual>
      <origin xyz="0 0 0"/>
      <geometry>
        <mesh filename="package://meshes/zx120-arm-cyl1.dae"/>
      </geometry>
    </visual>
    <collision>
      <origin xyz="0 0 0"/>
      <geometry>
        <mesh filename="package://meshes/zx120-arm-cyl1.dae"/>
      </geometry>
    </collision>
    <inertial>
      <origin rpy="0 0 0" xyz="0.696672 0.000026 -0.000065"/>
      <mass value="0.03"/>
      <inertia ixx="1.0" ixy="0.0" ixz="0.0" iyy="1.0" iyz="0.0" izz="1.0"/>
    </inertial>
  </link>

  <joint name="arm_rod_joint" type="prismatic">
    <origin xyz="0 0 0"/>
    <axis xyz="2.36471 0 0"/>
    <parent link="arm_cylinder_link"/>
    <child link="arm_rod_link"/>
    <limit effort="500" lower="-2" upper="2" velocity="6.159937255"/>
    <mimic joint="joint3" multiplier="0.458366236105"/>
  </joint>

  <link name="arm_rod_link">
    <visual>
      <origin xyz="0 0 0"/>
      <geometry>
        <mesh filename="package://meshes/zx120-arm-cyl2.dae"/>
      </geometry>
    </visual>
    <collision>
      <origin xyz="0 0 0"/>
      <geometry>
        <mesh filename="package://meshes/zx120-arm-cyl2.dae"/>
      </geometry>
    </collision>
    <inertial>
      <origin rpy="0 0 0" xyz="1.686736 -0.001027 -0.000662"/>
      <mass value="0.03"/>
      <inertia ixx="1.0" ixy="0.0" ixz="0.0" iyy="1.0" iyz="0.0" izz="1.0"/>
    </inertial>
  </link>



  <!-- bucket axis -->
  <!-- bucket main -->
  <joint name="bucket_joint" type="revolute">
    <origin rpy="0 0 0" xyz="0 0 2.519"/>
    <axis xyz="0 1 0"/>
    <parent link="arm_link"/>
    <child link="bucket_link"/>
    <limit effort="500" lower="-0.575958653158" upper="2.49582083035" velocity="6.159937255"/>
  </joint>

  <link name="bucket_link">
    <visual>
      <origin rpy="0 0.785398163375 0" xyz="0 0 0"/>
      <geometry>
        <mesh filename="package://zx120_description/meshes/zx120-bucket.dae"/>
      </geometry>
    </visual>
    <collision>
      <origin rpy="0 0.785398163375 0" xyz="0 0 0"/>
      <geometry>
        <mesh filename="package://zx120_description/meshes/zx120-bucket.dae"/>
      </geometry>
    </collision>
    <inertial>
      <origin rpy="0 0 0" xyz="-0.442405 0.001740 0.247894"/>
      <mass value="1"/>
      <inertia ixx="7.05333333333" ixy="0.0" ixz="0.0" iyy="0.0" iyz="0.0" izz="7.05333333333"/>
    </inertial>
  </link>
  <link name="bucket_end_link">
    <visual>
      <origin rpy="0 0 0" xyz="0 0 0"/>
      <geometry>
        <box size="0.001 0.001 0.001"/>
      </geometry>
      <material name="red"/>
    </visual>
    <inertial>
      <origin xyz="0 0 0"/>
      <mass value="1.0e-03"/>
      <inertia ixx="1.0e-03" ixy="0.0" ixz="0.0" iyy="1.0e-03" iyz="0.0" izz="1.0e-03"/>
    </inertial>
  </link>

  <joint name="bucket_end_joint" type="revolute">
    <parent link="bucket_link"/>
    <child link="bucket_end_link"/>
    <axis xyz="1 0 0"/>
    <origin rpy="0 0.872664625997 0" xyz="0 0 1.23"/>
    <limit effort="1" lower="-3.14" upper="3.14" velocity="0.5"/>
  </joint>

  <!-- <joint name="arm_cylinder_joint" type="fixed">
    <origin xyz="0.605825 0 -0.364793"/>
    <axis xyz="0 1 0"/>
    <parent link="arm_link"/>
    <child link="bucket_cylinder_link"/>
  </joint>

  <joint name="arm_rod_joint" type="prismatic">
    <origin xyz="0 0 0"/>
    <axis xyz="-0.021529 0 -2.207579"/>
    <parent link="arm_cylinder_link"/>
    <child link="bucket_rod_link"/>
    <limit effort="500" lower="-2" upper="2" velocity="6.159937255"/>
  </joint> -->


  <!-- bucket cylinder -->
  <link name="bucket_cylinder_link">
    <visual>
      <origin xyz="0 0 0"/>
      <geometry>
        <mesh filename="package://meshes/zx120-bucket-cyl1.dae"/>
      </geometry>
    </visual>
    <collision>
      <origin xyz="0 0 0"/>
      <geometry>
        <mesh filename="package://meshes/zx120-bucket-cyl1.dae"/>
      </geometry>
    </collision>
    <inertial>
      <origin rpy="0 0 0" xyz="-0.010342 0.000321 -0.639293"/>
      <mass value="0.03"/>
      <inertia ixx="1.0" ixy="0.0" ixz="0.0" iyy="1.0" iyz="0.0" izz="1.0"/>
    </inertial>
  </link>


  <joint name="bucket_rod_joint" type="prismatic">
    <origin xyz="0 0 0"/>
    <axis xyz="-0.021529 0 -2.207579"/>
    <parent link="link10"/>
    <child link="link11"/>
    <limit effort="500" lower="-2" upper="2" velocity="6.159937255"/>
    <mimic joint="joint4" multiplier="0.322580645161"/>
  </joint>


  <link name="bucket_rod_link">
    <visual>
      <origin xyz="0 0 0"/>
      <geometry>
        <mesh filename="package://meshes/zx120-bucket-cyl2.dae"/>
      </geometry>
    </visual>
    <collision>
      <origin xyz="0 0 0"/>
      <geometry>
        <mesh filename="package://meshes/zx120-bucket-cyl2.dae"/>
      </geometry>
    </collision>
    <inertial>
      <origin rpy="0 0 0" xyz="-0.015456 0.000321 -1.701647"/>
      <mass value="0.03"/>
      <inertia ixx="1.0" ixy="0.0" ixz="0.0" iyy="1.0" iyz="0.0" izz="1.0"/>
    </inertial>
  </link>



  <!-- bucket closed link -->
  <joint name="bucket_p1_joint" type="continuous">
    <origin xyz="0.330489 0 -2.150643"/>
    <axis xyz="0 1 0"/>
    <parent link="arm_link"/>
    <child link="bucket_p1_link"/>
    <mimic joint="joint4" multiplier="0.75"/>
  </joint>


  <joint name="bucket_p2_joint" type="continuous">
    <origin xyz="-0.182145 0 -0.315076"/>
    <axis xyz="0 1 0"/>
    <parent link="bucket_link"/>
    <child link="bucket_p2_link"/>
    <mimic joint="joint4" multiplier="-0.575"/>
  </joint>


  <link name="bucket_p1_link">
    <visual>
      <origin xyz="0 0 0"/>
      <geometry>
        <mesh filename="package://meshes/zx120-p1.dae"/>
      </geometry>
    </visual>
    <collision>
      <origin xyz="0 0 0"/>
      <geometry>
        <mesh filename="package://meshes/zx120-p1.dae"/>
      </geometry>
    </collision>
    <inertial>
      <origin rpy="0 0 0" xyz="0.126203 0.000026 -0.212651"/>
      <mass value="0.03"/>
      <inertia ixx="1.0" ixy="0.0" ixz="0.0" iyy="1.0" iyz="0.0" izz="1.0"/>
    </inertial>
  </link>

  <link name="bucket_p2_link">
    <visual>
      <origin xyz="0 0 0"/>
      <geometry>
        <mesh filename="package://meshes/zx120-p2.dae"/>
      </geometry>
    </visual>
    <collision>
      <origin xyz="0 0 0"/>
      <geometry>
        <mesh filename="package://meshes/zx120-p2.dae"/>
      </geometry>
    </collision>
    <inertial>
      <origin rpy="0 0 0" xyz="0.211197 0.000576 0.111406"/>
      <mass value="0.03"/>
      <inertia ixx="1.0" ixy="0.0" ixz="0.0" iyy="1.0" iyz="0.0" izz="1.0"/>
    </inertial>
  </link>

</robot>
