<?xml version="1.0" encoding="utf-8"?>
<!-- =================================================================================== -->
<!-- |    This document was autogenerated by xacro from zx120.xacro                    | -->
<!-- |    EDITING THIS FILE BY HAND IS NOT RECOMMENDED                                 | -->
<!-- =================================================================================== -->
<robot name="zx120">
  <!-- ros_control plugin -->
  <gazebo>
    <plugin filename="libgazebo_ros_control.so" name="gazebo_ros_control">
      <!-- <robotNamespace>/zx120</robotNamespace>
			<robotSimType>gazebo_ros_control/DefaultRobotHWSim</robotSimType> -->
    </plugin>
  </gazebo>
  <gazebo reference="track_link">
    <material>zx120texture</material>
  </gazebo>
  <gazebo reference="body_link">
    <material>zx120texture</material>
  </gazebo>
  <gazebo reference="boom_link">
    <material>zx120texture</material>
  </gazebo>
  <gazebo reference="arm_link">
    <material>zx120texture</material>
  </gazebo>
  <gazebo reference="bucket_link">
    <material>zx120texture</material>
  </gazebo>
  <gazebo reference="bucket_link">
    <material>zx120texture</material>
  </gazebo>
  <gazebo reference="boom_cylinder_head_link">
    <material>zx120texture</material>
  </gazebo>
  <gazebo reference="boom_cylinder_rod_link">
    <material>zx120texture</material>
  </gazebo>
  <gazebo reference="arm_cylinder_head_link">
    <material>zx120texture</material>
  </gazebo>
  <gazebo reference="arm_cylinder_rod_link">
    <material>zx120texture</material>
  </gazebo>
  <gazebo reference="bucket_cylinder_head_link">
    <material>zx120texture</material>
  </gazebo>
  <gazebo reference="bucket_cylinder_rod_link">
    <material>zx120texture</material>
  </gazebo>
  <gazebo reference="bucket_b_link">
    <material>zx120texture</material>
  </gazebo>
  <gazebo reference="bucket_a_link">
    <material>zx120texture</material>
  </gazebo>
  <!-- Import Rviz colors -->
  <!-- <xacro:include filename="$(find zx120_description)/urdf/materials.xacro" /> -->
  <!-- Base Link -->
  <link name="base_link"/>
  <joint name="base_joint" type="fixed">
    <parent link="base_link"/>
    <child link="track_link"/>
  </joint>
  <!-- Base Link -->
  <link name="track_link">
    <visual>
      <geometry>
        <mesh filename="package://zx120_description/meshes/zx120-crawler.dae"/>
      </geometry>
    </visual>
    <collision>
      <geometry>
        <mesh filename="package://zx120_description/meshes/zx120-crawler.dae"/>
      </geometry>
    </collision>
    <inertial>
      <origin rpy="0 0 0" xyz="-0.155869 0 0.358402"/>
      <mass value="10"/>
      <inertia ixx="1.0" ixy="0.0" ixz="0.0" iyy="1.0" iyz="0.0" izz="1.0"/>
    </inertial>
  </link>
  <!-- body axis -->
  <joint name="swing_joint" type="continuous">
    <origin xyz="0 0 1"/>
    <axis xyz="0 0 2"/>
    <parent link="track_link"/>
    <child link="body_link"/>
  </joint>
  <link name="body_link">
    <visual>
      <origin xyz="0 0 0"/>
      <geometry>
        <mesh filename="package://zx120_description/meshes/zx120-body.dae"/>
      </geometry>
    </visual>
    <collision>
      <origin xyz="0 0 0"/>
      <geometry>
        <mesh filename="package://zx120_description/meshes/zx120-body.dae"/>
      </geometry>
    </collision>
    <inertial>
      <origin rpy="0 0 0" xyz="-0.501522 0 1.191169"/>
      <mass value="0.03"/>
      <inertia ixx="1.0" ixy="0.0" ixz="0.0" iyy="1.0" iyz="0.0" izz="1.0"/>
    </inertial>
  </link>
  <!-- boom axis -->
  <joint name="boom_joint" type="revolute">
    <origin rpy="0 1.57079632679 0" xyz="0.14 -0.16443 0.424"/>
    <axis xyz="0 1 0"/>
    <parent link="body_link"/>
    <child link="boom_link"/>
    <limit effort="500" lower="-1.2217304764" upper="0.767944870878" velocity="6.159937255"/>
  </joint>
  <link name="boom_link">
    <visual>
      <origin rpy="0 -1.185 0" xyz="0 0 0"/>
      <geometry>
        <mesh filename="package://zx120_description/meshes/zx120-boom.dae"/>
      </geometry>
    </visual>
    <collision>
      <origin rpy="0 -1.185 0" xyz="0 0 0"/>
      <geometry>
        <mesh filename="package://zx120_description/meshes/zx120-boom.dae"/>
      </geometry>
    </collision>
    <inertial>
      <origin rpy="0 0 0" xyz="2.091062 0.055029 0.975556"/>
      <mass value="0.03"/>
      <inertia ixx="1.0" ixy="0.0" ixz="0.0" iyy="1.0" iyz="0.0" izz="1.0"/>
    </inertial>
  </link>
  <joint name="arm_joint" type="revolute">
    <!-- <origin xyz="3.91812248 0 2.410044861"/> -->
    <origin xyz="0 0 4.6"/>
    <axis xyz="0 1 0"/>
    <parent link="boom_link"/>
    <child link="arm_link"/>
    <!-- <limit lower="-1.279421828" upper="0.849879859" effort="500" velocity="6.159937255"/> -->
    <limit effort="1" lower="0.523598775598" upper="2.65290046303" velocity="0.5"/>
  </joint>
  <link name="arm_link">
    <visual>
      <origin rpy="0 3.28 0" xyz="0 0 0"/>
      <geometry>
        <mesh filename="package://zx120_description/meshes/zx120-arm.dae"/>
      </geometry>
    </visual>
    <collision>
      <origin rpy="0 3.28 0" xyz="0 0 0"/>
      <geometry>
        <mesh filename="package://zx120_description/meshes/zx120-arm.dae"/>
      </geometry>
    </collision>
    <inertial>
      <origin rpy="0 0 0" xyz="0.305996 0.000026 -0.912806"/>
      <mass value="0.03"/>
      <inertia ixx="1.0" ixy="0.0" ixz="0.0" iyy="1.0" iyz="0.0" izz="1.0"/>
    </inertial>
  </link>
  <!-- bucket axis -->
  <joint name="bucket_joint" type="revolute">
    <!-- <origin xyz="0.790541414 0 -2.391736874"/> -->
    <origin xyz="0 0 2.519"/>
    <axis xyz="0 1 0"/>
    <parent link="arm_link"/>
    <child link="bucket_link"/>
    <!-- <limit lower="-1.593223372" upper="1.478556111" effort="500" velocity="6.159937255"/> -->
    <limit effort="1" lower="-0.575958653158" upper="2.49582083035" velocity="0.5"/>
  </joint>
  <link name="bucket_link">
    <visual>
      <origin rpy="0 0.75 0" xyz="0 0 0"/>
      <geometry>
        <mesh filename="package://zx120_description/meshes/zx120-bucket.dae"/>
      </geometry>
    </visual>
    <collision>
      <origin xyz="0 0 0"/>
      <geometry>
        <mesh filename="package://zx120_description/meshes/zx120-bucket.dae"/>
      </geometry>
    </collision>
    <inertial>
      <origin rpy="0 0 0" xyz="-0.442405 0.001740 0.247894"/>
      <mass value="0.03"/>
      <inertia ixx="1.0" ixy="0.0" ixz="0.0" iyy="1.0" iyz="0.0" izz="1.0"/>
    </inertial>
  </link>
  <link name="bucket_end_link">
    <visual>
      <origin rpy="0 0 0" xyz="0 0 0"/>
      <geometry>
        <box size="0.001 0.001 0.001"/>
      </geometry>
      <material name="red"/>
    </visual>
    <inertial>
      <origin xyz="0 0 0"/>
      <mass value="1.0e-03"/>
      <inertia ixx="1.0e-03" ixy="0.0" ixz="0.0" iyy="1.0e-03" iyz="0.0" izz="1.0e-03"/>
    </inertial>
  </link>
  <joint name="bucket_end_joint" type="revolute">
    <parent link="bucket_link"/>
    <child link="bucket_end_link"/>
    <axis xyz="1 0 0"/>
    <!-- <origin rpy="0 0 0" xyz="0 0 1.23"/> -->
    <!-- <origin rpy="0 0 0" xyz="-0.723 0 0.995"/> -->
    <!-- <origin rpy="0 0 0" xyz="-0.85 0 0.889"/> -->
    <origin rpy="0 0.872664625997 0" xyz="0 0 1.23"/>
    <limit effort="1" lower="-3.14" upper="3.14" velocity="0.5"/>
  </joint>
  <transmission name="tran1">
    <type>transmission_interface/SimpleTransmission</type>
    <joint name="swing_joint">
      <hardwareInterface>hardware_interface/PositionJointInterface</hardwareInterface>
    </joint>
    <actuator name="motor1">
      <hardwareInterface>hardware_interface/PositionJointInterface</hardwareInterface>
      <mechanicalReduction>1</mechanicalReduction>
    </actuator>
  </transmission>
  <transmission name="tran2">
    <type>transmission_interface/SimpleTransmission</type>
    <joint name="boom_joint">
      <hardwareInterface>hardware_interface/PositionJointInterface</hardwareInterface>
    </joint>
    <actuator name="motor2">
      <hardwareInterface>hardware_interface/PositionJointInterface</hardwareInterface>
      <mechanicalReduction>1</mechanicalReduction>
    </actuator>
  </transmission>
  <transmission name="tran3">
    <type>transmission_interface/SimpleTransmission</type>
    <joint name="arm_joint">
      <hardwareInterface>hardware_interface/PositionJointInterface</hardwareInterface>
    </joint>
    <actuator name="motor3">
      <hardwareInterface>hardware_interface/PositionJointInterface</hardwareInterface>
      <mechanicalReduction>1</mechanicalReduction>
    </actuator>
  </transmission>
  <transmission name="tran4">
    <type>transmission_interface/SimpleTransmission</type>
    <joint name="bucket_joint">
      <hardwareInterface>hardware_interface/PositionJointInterface</hardwareInterface>
    </joint>
    <actuator name="motor4">
      <hardwareInterface>hardware_interface/PositionJointInterface</hardwareInterface>
      <mechanicalReduction>1</mechanicalReduction>
    </actuator>
  </transmission>
  <transmission name="dummy_trans1">
    <type>transmission_interface/SimpleTransmission</type>
    <joint name="bucket_end_joint">
      <hardwareInterface>hardware_interface/PositionJointInterface</hardwareInterface>
    </joint>
    <actuator name="dummy_motor1">
      <hardwareInterface>hardware_interface/PositionJointInterface</hardwareInterface>
      <mechanicalReduction>1</mechanicalReduction>
    </actuator>
  </transmission>
</robot>
