<?xml version="1.0" ?>
<!-- =================================================================================== -->
<!-- |    This document was autogenerated by xacro from c30r.xacro                     | -->
<!-- |    EDITING THIS FILE BY HAND IS NOT RECOMMENDED                                 | -->
<!-- =================================================================================== -->
<robot name="c30r">
  <!-- Import all Gazebo-customization elements, including Gazebo colors -->
  <!-- <xacro:include filename="$(find ic120_description)/urdf/ic120.gazebo" /> -->
  <!-- Import Rviz colors -->
  <!-- <xacro:include filename="$(find ic120_description)/urdf/materials.xacro" /> -->
  <!-- Base Link -->
  <link name="base_link">
    <visual>
      <geometry>
        <mesh filename="package://meshes/c30r-body.dae"/>
      </geometry>
    </visual>
    <inertial>
      <origin rpy="0 0 0" xyz="0 0 0"/>
      <mass value="0.1"/>
      <inertia ixx="1.0" ixy="0.0" ixz="0.0" iyy="1.0" iyz="0.0" izz="1.0"/>
    </inertial>
  </link>
  <!-- left sprocket axis -->
  <!--
	<joint name="sprocket_left_joint" type="continuous">
		<origin xyz="-2.35 1 0.65"/>
		<axis xyz="0 1 0"/>
		<parent link="base_link"/>
		<child link="left_sprocket_link"/>
	</joint>
	<link name="left_sprocket_link"/> 
	-->
  <!-- right sprocket axis -->
  <!--
	<joint name="sprocket_right_joint" type="continuous">
		<origin xyz="-2.35 -1 0.65"/>
		<axis xyz="0 1 0"/>
		<parent link="base_link"/>
		<child link="right_sprocket_link"/>
	</joint>
	<link name="right_sprocket_link"/> 
	-->
  <!-- vessel axis -->
  <joint name="vessel_pin_joint" type="revolute">
    <origin xyz="-1.2458 0 0.67135"/>
    <axis xyz="0 1 0"/>
    <parent link="base_link"/>
    <child link="vessel_link"/>
    <limit effort="30" lower="-1.0122909661567112" upper="0" velocity="6.159937255"/>
  </joint>
  <link name="vessel_link">
    <visual>
      <geometry>
        <mesh filename="package://meshes/c30r-vessel1.dae"/>
      </geometry>
    </visual>
    <inertial>
      <origin rpy="0 0 0" xyz="0 0 0"/>
      <mass value="0.1"/>
      <inertia ixx="1.0" ixy="0.0" ixz="0.0" iyy="1.0" iyz="0.0" izz="1.0"/>
    </inertial>
  </link>
  <joint name="tailgate_joint" type="continuous">
    <origin xyz="-0.24718 0 0.66873"/>
    <axis xyz="0 1 0"/>
    <parent link="vessel_link"/>
    <child link="tailgate_link"/>
    <mimic joint="vessel_pin_joint" multiplier="-1"/>
  </joint>
  <link name="tailgate_link">
    <visual>
      <geometry>
        <mesh filename="package://meshes/c30r-vessel2.dae"/>
      </geometry>
    </visual>
    <inertial>
      <origin rpy="0 0 0" xyz="0 0 0"/>
      <mass value="0.1"/>
      <inertia ixx="1.0" ixy="0.0" ixz="0.0" iyy="1.0" iyz="0.0" izz="1.0"/>
    </inertial>
  </link>
 
  <transmission name="tran1">
    <type>transmission_interface/SimpleTransmission</type>
    <joint name="vessel_pin_joint">
      <hardwareInterface>hardware_interface/EffortJointInterface</hardwareInterface>
    </joint>
    <actuator name="vessel_pin_joint_motor">
      <hardwareInterface>hardware_interface/EffortJointInterface</hardwareInterface>
      <mechanicalReduction>1</mechanicalReduction>
    </actuator>
  </transmission>

  <joint name="left_middle_wheel_joint" type="continuous">
    <origin rpy="-1.5707963267948966 0 0" xyz="-0.05 0.615 0.25"/>
    <parent link="base_link"/>
    <child link="left_middle_wheel_link"/>
    <axis xyz="0 0 1"/>
  </joint>
  <transmission name="left_middle_wheel_trans" type="SimpleTransmission">
    <type>transmission_interface/SimpleTransmission</type>
    <actuator name="left_middle_wheel_motor">
      <mechanicalReduction>1</mechanicalReduction>
    </actuator>
    <joint name="left_middle_wheel_joint">
      <hardwareInterface>hardware_interface/VelocityJointInterface</hardwareInterface>
    </joint>
  </transmission>
  <link name="left_middle_wheel_link">
    <inertial>
      <origin rpy="0 0 0" xyz="0 0 0"/>
      <mass value="10"/>
      <inertia ixx="5" ixy="0.0" ixz="0.0" iyy="5" iyz="0.0" izz="5"/>
    </inertial>
    <!-- <visual>
        <geometry>
          <cylinder radius="0.5" length="0.5" />
        </geometry>
      </visual> -->
    <collision>
      <geometry>
        <cylinder length="0.1" radius="0.25"/>
      </geometry>
    </collision>
  </link>
  <gazebo reference="left_middle_wheel_link">
    <!--material>Gazebo/Red</material-->
    <mu1 value="0.7"/>
    <mu2 value="0.6"/>
    <kp value="7.5e+5"/>
    <kd value="0.001"/>
  </gazebo>
  <joint name="left_front_wheel_joint" type="continuous">
    <origin rpy="-1.5707963267948966 0 0" xyz="0.6 0.615 0.25"/>
    <parent link="base_link"/>
    <child link="left_front_wheel_link"/>
    <axis xyz="0 0 1"/>
  </joint>
  <transmission name="left_front_wheel_trans" type="SimpleTransmission">
    <type>transmission_interface/SimpleTransmission</type>
    <actuator name="left_front_wheel_motor">
      <mechanicalReduction>1</mechanicalReduction>
    </actuator>
    <joint name="left_front_wheel_joint">
      <hardwareInterface>hardware_interface/VelocityJointInterface</hardwareInterface>
    </joint>
  </transmission>
  <link name="left_front_wheel_link">
    <inertial>
      <origin rpy="0 0 0" xyz="0 0 0"/>
      <mass value="10"/>
      <inertia ixx="5" ixy="0.0" ixz="0.0" iyy="5" iyz="0.0" izz="5"/>
    </inertial>
    <!-- <visual>
        <geometry>
          <cylinder radius="0.5" length="0.5" />
        </geometry>
      </visual> -->
    <collision>
      <geometry>
        <cylinder length="0.1" radius="0.25"/>
      </geometry>
    </collision>
  </link>
  <gazebo reference="left_front_wheel_link">
    <!--material>Gazebo/Red</material-->
    <mu1 value="0.7"/>
    <mu2 value="0.6"/>
    <kp value="7.5e+5"/>
    <kd value="0.001"/>
  </gazebo>

  <joint name="left_rear_wheel_joint" type="continuous">
    <origin rpy="-1.5707963267948966 0 0" xyz="-0.7 0.615 0.25"/>
    <parent link="base_link"/>
    <child link="left_rear_wheel_link"/>
    <axis xyz="0 0 1"/>
  </joint>
  <transmission name="left_rear_wheel_trans" type="SimpleTransmission">
    <type>transmission_interface/SimpleTransmission</type>
    <actuator name="left_rear_wheel_motor">
      <mechanicalReduction>1</mechanicalReduction>
    </actuator>
    <joint name="left_rear_wheel_joint">
      <hardwareInterface>hardware_interface/VelocityJointInterface</hardwareInterface>
    </joint>
  </transmission>
  <link name="left_rear_wheel_link">
    <inertial>
      <origin rpy="0 0 0" xyz="0 0 0"/>
      <mass value="10"/>
      <inertia ixx="5" ixy="0.0" ixz="0.0" iyy="5" iyz="0.0" izz="5"/>
    </inertial>
    <!-- <visual>
        <geometry>
          <cylinder radius="0.5" length="0.5" />
        </geometry>
      </visual> -->
    <collision>
      <geometry>
        <cylinder length="0.1" radius="0.25"/>
      </geometry>
    </collision>
  </link>
  <gazebo reference="left_rear_wheel_link">
    <!--material>Gazebo/Red</material-->
    <mu1 value="0.7"/>
    <mu2 value="0.6"/>
    <kp value="7.5e+5"/>
    <kd value="0.001"/>
  </gazebo>
  <joint name="right_middle_wheel_joint" type="continuous">
    <origin rpy="-1.5707963267948966 0 0" xyz="-0.05 -0.615 0.25"/>
    <parent link="base_link"/>
    <child link="right_middle_wheel_link"/>
    <axis xyz="0 0 1"/>
  </joint>
  <transmission name="right_middle_wheel_trans" type="SimpleTransmission">
    <type>transmission_interface/SimpleTransmission</type>
    <actuator name="right_middle_wheel_motor">
      <mechanicalReduction>1</mechanicalReduction>
    </actuator>
    <joint name="right_middle_wheel_joint">
      <hardwareInterface>hardware_interface/VelocityJointInterface</hardwareInterface>
    </joint>
  </transmission>
  <link name="right_middle_wheel_link">
    <inertial>
      <origin rpy="0 0 0" xyz="0 0 0"/>
      <mass value="10"/>
      <inertia ixx="5" ixy="0.0" ixz="0.0" iyy="5" iyz="0.0" izz="5"/>
    </inertial>
    <!-- <visual>
        <geometry>
          <cylinder radius="0.5" length="0.5" />
        </geometry>
      </visual> -->
    <collision>
      <geometry>
        <cylinder length="0.1" radius="0.25"/>
      </geometry>
    </collision>
  </link>
  <gazebo reference="right_middle_wheel_link">
    <!--material>Gazebo/Red</material-->
    <mu1 value="0.7"/>
    <mu2 value="0.6"/>
    <kp value="7.5e+5"/>
    <kd value="0.001"/>
  </gazebo>
  <joint name="right_front_wheel_joint" type="continuous">
    <origin rpy="-1.5707963267948966 0 0" xyz="0.6 -0.615 0.25"/>
    <parent link="base_link"/>
    <child link="right_front_wheel_link"/>
    <axis xyz="0 0 1"/>
  </joint>
  <transmission name="right_front_wheel_trans" type="SimpleTransmission">
    <type>transmission_interface/SimpleTransmission</type>
    <actuator name="right_front_wheel_motor">
      <mechanicalReduction>1</mechanicalReduction>
    </actuator>
    <joint name="right_front_wheel_joint">
      <hardwareInterface>hardware_interface/VelocityJointInterface</hardwareInterface>
    </joint>
  </transmission>
  <link name="right_front_wheel_link">
    <inertial>
      <origin rpy="0 0 0" xyz="0 0 0"/>
      <mass value="10"/>
      <inertia ixx="5" ixy="0.0" ixz="0.0" iyy="5" iyz="0.0" izz="5"/>
    </inertial>
    <!-- <visual>
        <geometry>
          <cylinder radius="0.5" length="0.5" />
        </geometry>
      </visual> -->
    <collision>
      <geometry>
        <cylinder length="0.1" radius="0.25"/>
      </geometry>
    </collision>
  </link>
  <gazebo reference="right_front_wheel_link">
    <!--material>Gazebo/Red</material-->
    <mu1 value="0.7"/>
    <mu2 value="0.6"/>
    <kp value="7.5e+5"/>
    <kd value="0.001"/>
  </gazebo>

  <joint name="right_rear_wheel_joint" type="continuous">
    <origin rpy="-1.5707963267948966 0 0" xyz="-0.7 -0.615 0.25"/>
    <parent link="base_link"/>
    <child link="right_rear_wheel_link"/>
    <axis xyz="0 0 1"/>
  </joint>
  <transmission name="right_rear_wheel_trans" type="SimpleTransmission">
    <type>transmission_interface/SimpleTransmission</type>
    <actuator name="right_rear_wheel_motor">
      <mechanicalReduction>1</mechanicalReduction>
    </actuator>
    <joint name="right_rear_wheel_joint">
      <hardwareInterface>hardware_interface/VelocityJointInterface</hardwareInterface>
    </joint>
  </transmission>
  <link name="right_rear_wheel_link">
    <inertial>
      <origin rpy="0 0 0" xyz="0 0 0"/>
      <mass value="10"/>
      <inertia ixx="5" ixy="0.0" ixz="0.0" iyy="5" iyz="0.0" izz="5"/>
    </inertial>
    <!-- <visual>
        <geometry>
          <cylinder radius="0.5" length="0.5" />
        </geometry>
      </visual> -->
    <collision>
      <geometry>
        <cylinder length="0.1" radius="0.25"/>
      </geometry>
    </collision>
  </link>
  <gazebo reference="right_rear_wheel_link">
    <!--material>Gazebo/Red</material-->
    <mu1 value="0.7"/>
    <mu2 value="0.6"/>
    <kp value="7.5e+5"/>
    <kd value="0.001"/>
  </gazebo>

  <disable_collision link1="base_link" link2="vessel_link"></disable_collision>
  <disable_collision link1="vessel_link" link2="tailgate_link"></disable_collision>
</robot>
