<?xml version="1.0" ?>
<!-- =================================================================================== -->
<!-- |    This document was autogenerated by xacro from d37pxi24.xacro                 | -->
<!-- |    EDITING THIS FILE BY HAND IS NOT RECOMMENDED                                 | -->
<!-- =================================================================================== -->
<robot name="d37pxi24">
  <!-- Base Link -->
  <link name="base_link"/>
  <!-- Body {{{ -->
  <joint name="base_joint" type="fixed">
    <parent link="base_link"/>
    <child link="body_link"/>
  </joint>
  <link name="body_link">
    <visual>
      <geometry>
        <mesh filename="package://meshes/d37pxi24-body.dae"/>
      </geometry>
    </visual>
    <collision>
      <geometry>
        <mesh filename="package://meshes/d37pxi24-body.dae"/>
      </geometry>
    </collision>
    <inertial>
      <origin rpy="0 0 0" xyz="0 0 0"/>
      <mass value="0.03"/>
      <inertia ixx="1.0" ixy="0.0" ixz="0.0" iyy="1.0" iyz="0.0" izz="1.0"/>
    </inertial>
  </link>
  <!-- }}} Body ends here -->
  <!-- Blade Arm {{{ -->
  <joint name="blade_arm_joint" type="revolute">
    <origin xyz="0.6718 0 0.38606"/>
    <axis xyz="0 1 0"/>
    <parent link="body_link"/>
    <child link="blade_arm_link"/>
    <limit effort="500" lower="-0.41015237421866746" upper="0.18675022996339324" velocity="6.159937255"/>
  </joint>
  <link name="blade_arm_link">
    <visual>
      <origin xyz="0 0 0"/>
      <geometry>
        <mesh filename="package://meshes/d37pxi24-blade-arm.dae"/>
      </geometry>
    </visual>
    <collision>
      <origin xyz="0 0 0"/>
      <geometry>
        <mesh filename="package://meshes/d37pxi24-blade-arm.dae"/>
      </geometry>
    </collision>
    <inertial>
      <origin rpy="0 0 0" xyz="0 0 0"/>
      <mass value="0.03"/>
      <inertia ixx="1.0" ixy="0.0" ixz="0.0" iyy="1.0" iyz="0.0" izz="1.0"/>
    </inertial>
  </link>
  <!-- }}} Blade Arm ends here -->
  <!-- Blade Arm Cylinder {{{ -->
  <joint name="blade_arm_cylinder_joint" type="continuous">
    <origin xyz="0.54437 0 0.90368"/>
    <axis xyz="0 1 0"/>
    <parent link="body_link"/>
    <child link="blade_arm_cylinder_link"/>
    <mimic joint="blade_arm_joint" multiplier="0.9"/>
  </joint>
  <link name="blade_arm_cylinder_link">
    <visual>
      <origin xyz="0 0 0"/>
      <geometry>
        <mesh filename="package://meshes/d37pxi24-blade-arm-cylinder.dae"/>
      </geometry>
    </visual>
    <collision>
      <origin xyz="0 0 0"/>
      <geometry>
        <mesh filename="package://meshes/d37pxi24-blade-arm-cylinder.dae"/>
      </geometry>
    </collision>
    <inertial>
      <origin rpy="0 0 0" xyz="0 0 0"/>
      <mass value="0.03"/>
      <inertia ixx="1.0" ixy="0.0" ixz="0.0" iyy="1.0" iyz="0.0" izz="1.0"/>
    </inertial>
  </link>
  <!-- }}} Blade Arm Cylinder ends here -->
  <!-- Blade Arm Piston {{{ -->
  <joint name="blade_arm_piston_joint" type="prismatic">
    <origin xyz="0 0 0"/>
    <axis xyz="1.0055 0 -0.056785"/>
    <parent link="blade_arm_cylinder_link"/>
    <child link="blade_arm_piston_link"/>
    <limit effort="500" lower="-0.22" upper="0.05" velocity="6.159937255"/>
    <mimic joint="blade_arm_cylinder_joint" multiplier="0.6"/>
  </joint>
  <link name="blade_arm_piston_link">
    <visual>
      <origin xyz="0 0 0"/>
      <geometry>
        <mesh filename="package://meshes/d37pxi24-blade-arm-piston.dae"/>
      </geometry>
    </visual>
    <collision>
      <origin xyz="0 0 0"/>
      <geometry>
        <mesh filename="package://meshes/d37pxi24-blade-arm-piston.dae"/>
      </geometry>
    </collision>
    <inertial>
      <origin rpy="0 0 0" xyz="0 0 0"/>
      <mass value="0.03"/>
      <inertia ixx="1.0" ixy="0.0" ixz="0.0" iyy="1.0" iyz="0.0" izz="1.0"/>
    </inertial>
  </link>
  <!-- }}} Blade Arm Piston ends here -->
  <!-- Blade Angle {{{ -->
  <joint name="blade_angle_joint" type="revolute">
    <origin xyz="1.5881 0 -0.10373"/>
    <axis xyz="0 0 1"/>
    <parent link="blade_arm_link"/>
    <child link="blade_angle_link"/>
    <limit effort="500" lower="-0.4188790204786391" upper="0.4188790204786391" velocity="6.159937255"/>
  </joint>
  <link name="blade_angle_link"/>
  <!-- }}} Blade Angle ends here -->
  <!-- Blade Angle Piston Right {{{ -->
  <joint name="blade_angle_piston_right_joint" type="prismatic">
    <origin xyz="0.50775 -0.44941 0.18324"/>
    <axis xyz="1.093 -0.059226 -0.062315"/>
    <parent link="blade_arm_link"/>
    <child link="blade_angle_piston_right_link"/>
    <limit effort="500" lower="-0.24" upper="0.18" velocity="6.159937255"/>
    <mimic joint="blade_angle_joint" multiplier="0.5"/>
  </joint>
  <link name="blade_angle_piston_right_link">
    <visual>
      <origin xyz="0 0 0"/>
      <geometry>
        <mesh filename="package://meshes/d37pxi24-blade-angle-piston-right.dae"/>
      </geometry>
    </visual>
    <collision>
      <origin xyz="0 0 0"/>
      <geometry>
        <mesh filename="package://meshes/d37pxi24-blade-angle-piston-right.dae"/>
      </geometry>
    </collision>
    <inertial>
      <origin rpy="0 0 0" xyz="0 0 0"/>
      <mass value="0.03"/>
      <inertia ixx="1.0" ixy="0.0" ixz="0.0" iyy="1.0" iyz="0.0" izz="1.0"/>
    </inertial>
  </link>
  <!-- }}} Blade Angle Piston Right ends here -->
  <!-- Blade Angle Piston Left {{{ -->
  <joint name="blade_angle_piston_left_joint" type="prismatic">
    <origin xyz="0.50775 0.44941 0.18324"/>
    <axis xyz="1.093 0.059226 -0.062315"/>
    <parent link="blade_arm_link"/>
    <child link="blade_angle_piston_left_link"/>
    <limit effort="500" lower="-0.24" upper="0.18" velocity="6.159937255"/>
    <mimic joint="blade_angle_joint" multiplier="-0.5"/>
  </joint>
  <link name="blade_angle_piston_left_link">
    <visual>
      <origin xyz="0 0 0"/>
      <geometry>
        <mesh filename="package://meshes/d37pxi24-blade-angle-piston-left.dae"/>
      </geometry>
    </visual>
    <collision>
      <origin xyz="0 0 0"/>
      <geometry>
        <mesh filename="package://meshes/d37pxi24-blade-angle-piston-left.dae"/>
      </geometry>
    </collision>
    <inertial>
      <origin rpy="0 0 0" xyz="0 0 0"/>
      <mass value="0.03"/>
      <inertia ixx="1.0" ixy="0.0" ixz="0.0" iyy="1.0" iyz="0.0" izz="1.0"/>
    </inertial>
  </link>
  <!-- }}} Blade Angle Piston Left ends here -->
  <!-- Blade Tilt {{{ -->
  <joint name="blade_tilt_joint" type="revolute">
    <origin xyz="0 0 0"/>
    <axis xyz="1 0 0"/>
    <parent link="blade_angle_link"/>
    <child link="blade_link"/>
    <limit effort="500" lower="-0.1363596851440582" upper="0.1363596851440582" velocity="6.159937255"/>
  </joint>
  <link name="blade_link">
    <visual>
      <origin xyz="0 0 0"/>
      <geometry>
        <mesh filename="package://meshes/d37pxi24-blade.dae"/>
      </geometry>
    </visual>
    <collision>
      <origin xyz="0 0 0"/>
      <geometry>
        <mesh filename="package://meshes/d37pxi24-blade.dae"/>
      </geometry>
    </collision>
    <inertial>
      <origin rpy="0 0 0" xyz="0 0 0"/>
      <mass value="0.03"/>
      <inertia ixx="1.0" ixy="0.0" ixz="0.0" iyy="1.0" iyz="0.0" izz="1.0"/>
    </inertial>
  </link>
  <!-- }}} Blade Tilt ends here -->
</robot>
